Workbook
Name EURKUR: 'CSM PRICE LIST 26.1.3'!$E$1

Sheet CSM  PRICE LIST 26.1.3
A1: PRICE LIST VER.: | B1: v.26.1.3 | C1: Valid Through: 01.01.26 - 31.06.26 | D1: € kur- €/$ parite | E1: 55 | F1: 1.15
A2: STYLE NAMES | B2: CATEGORY | C2: ÜRÜN ADI | D2: € PRICE | E2: TL PRICE | F2: USD PRICE | G2: PRODUCT NAME
A3: FERNANDO | B3: =+VLOOKUP($A3,'[1]STYLE NAMES'!$B:$O,4,FALSE) -> ACCESSORIES | C3: =+VLOOKUP($A3,'[1]STYLE NAMES'!$B:$O,14,FALSE) -> ANAHTARLIK | D3: 12.9 | E3: =ROUNDDOWN(+D3*EURKUR,-1) -> 700 | F3: =+D3*$F$1 -> 14.835 | G3: =+VLOOKUP($A3,'[1]STYLE NAMES'!$B:$O,2,FALSE) -> KEY RING
A4: NANDO | B4: =+VLOOKUP($A4,'[1]STYLE NAMES'!$B:$O,4,FALSE) -> ACCESSORIES | C4: =+VLOOKUP($A4,'[1]STYLE NAMES'!$B:$O,14,FALSE) -> İSİM KÜNYESİ | D4: 12.9 | E4: =ROUNDDOWN(+D4*EURKUR,-1) -> 700 | F4: =+D4*$F$1 -> 14.835 | G4: =+VLOOKUP($A4,'[1]STYLE NAMES'!$B:$O,2,FALSE) -> NAME TAG
A5: BANDANA | B5: =+VLOOKUP($A5,'[1]STYLE NAMES'!$B:$O,4,FALSE) -> ACCESSORIES | C5: =+VLOOKUP($A5,'[1]STYLE NAMES'!$B:$O,14,FALSE) -> BANDANA | D5: 12.9 | E5: =ROUNDDOWN(+D5*EURKUR,-1) -> 700 | F5: =+D5*$F$1 -> 14.835 | G5: =+VLOOKUP($A5,'[1]STYLE NAMES'!$B:$O,2,FALSE) -> HEADBAND
A6: CAPE TOWN | B6: =+VLOOKUP($A6,'[1]STYLE NAMES'!$B:$O,4,FALSE) -> ACCESSORIES | C6: =+VLOOKUP($A6,'[1]STYLE NAMES'!$B:$O,14,FALSE) -> KEP ŞAPKA | D6: 29.9 | E6: =ROUNDDOWN(+D6*EURKUR,-1) -> 1640 | F6: =+D6*$F$1 -> 34.385 | G6: =+VLOOKUP($A6,'[1]STYLE NAMES'!$B:$O,2,FALSE) -> BASEBALL CAP
A7: OTTAWA | B7: =+VLOOKUP($A7,'[1]STYLE NAMES'!$B:$O,4,FALSE) -> ACCESSORIES | C7: =+VLOOKUP($A7,'[1]STYLE NAMES'!$B:$O,14,FALSE) -> BERE ŞAPKA | D7: 29.9 | E7: =ROUNDDOWN(+D7*EURKUR,-1) -> 1640 | F7: =+D7*$F$1 -> 34.385 | G7: =+VLOOKUP($A7,'[1]STYLE NAMES'!$B:$O,2,FALSE) -> BEANIE
A8: CAPRI-3XB | B8: =+VLOOKUP($A8,'[1]STYLE NAMES'!$B:$O,4,FALSE) -> ACCESSORIES | C8: =+VLOOKUP($A8,'[1]STYLE NAMES'!$B:$O,14,FALSE) -> YAZLIK BİNİCİ ÇORABI 3'LÜ PAKET | D8: 34.9 | E8: =ROUNDDOWN(+D8*EURKUR,-1) -> 1910 | F8: =+D8*$F$1 -> 40.135 | G8: =+VLOOKUP($A8,'[1]STYLE NAMES'!$B:$O,2,FALSE) -> SUMMER RIDING SOCKS 3 PACK BUNDLE
A9: LAZIO-3XB | B9: =+VLOOKUP($A9,'[1]STYLE NAMES'!$B:$O,4,FALSE) -> ACCESSORIES | C9: =+VLOOKUP($A9,'[1]STYLE NAMES'!$B:$O,14,FALSE) -> GEO 4 MEVSİM BİNİCİ ÇORABI 3'LÜ PAKET | D9: 34.9 | E9: =ROUNDDOWN(+D9*EURKUR,-1) -> 1910 | F9: =+D9*$F$1 -> 40.135 | G9: =+VLOOKUP($A9,'[1]STYLE NAMES'!$B:$O,2,FALSE) -> GEO ALL-SEASON RIDING SOCKS 3 PACK BUNDLE
A10: LUCCA-3XB | B10: =+VLOOKUP($A10,'[1]STYLE NAMES'!$B:$O,4,FALSE) -> ACCESSORIES | C10: =+VLOOKUP($A10,'[1]STYLE NAMES'!$B:$O,14,FALSE) -> ÇOCUK BİNİCİ ÇORABI 3'LÜ PAKET | D10: 34.9 | E10: =ROUNDDOWN(+D10*EURKUR,-1) -> 1910 | F10: =+D10*$F$1 -> 40.135 | G10: =+VLOOKUP($A10,'[1]STYLE NAMES'!$B:$O,2,FALSE) -> KID'S RIDING SOCKS 3 PACK BUNDLE
A11: CAMBRIDGE | B11: =+VLOOKUP($A11,'[1]STYLE NAMES'!$B:$O,4,FALSE) -> ACCESSORIES | C11: =+VLOOKUP($A11,'[1]STYLE NAMES'!$B:$O,14,FALSE) -> YARIŞMA KRAVATI | D11: 39.9 | E11: =ROUNDDOWN(+D11*EURKUR,-1) -> 2190 | F11: =+D11*$F$1 -> 45.885 | G11: =+VLOOKUP($A11,'[1]STYLE NAMES'!$B:$O,2,FALSE) -> COMPETITION TIE
A12: FONDI-3XB | B12: =+VLOOKUP($A12,'[1]STYLE NAMES'!$B:$O,4,FALSE) -> ACCESSORIES | C12: =+VLOOKUP($A12,'[1]STYLE NAMES'!$B:$O,14,FALSE) -> 4 MEVSİM BİNİCİ ÇORABI 3'LÜ PAKET | D12: 39.9 | E12: =ROUNDDOWN(+D12*EURKUR,-1) -> 2190 | F12: =+D12*$F$1 -> 45.885 | G12: =+VLOOKUP($A12,'[1]STYLE NAMES'!$B:$O,2,FALSE) -> 4 SEASON RIDING SOCKS 3 PACK BUNDLE
A13: OXFORD | B13: =+VLOOKUP($A13,'[1]STYLE NAMES'!$B:$O,4,FALSE) -> ACCESSORIES | C13: =+VLOOKUP($A13,'[1]STYLE NAMES'!$B:$O,14,FALSE) -> ÖRME YARIŞMA KRAVATI | D13: 39.9 | E13: =ROUNDDOWN(+D13*EURKUR,-1) -> 2190 | F13: =+D13*$F$1 -> 45.885 | G13: =+VLOOKUP($A13,'[1]STYLE NAMES'!$B:$O,2,FALSE) -> KNIT COMPETITION TIE
A14: ROMA-3XB | B14: =+VLOOKUP($A14,'[1]STYLE NAMES'!$B:$O,4,FALSE) -> ACCESSORIES | C14: =+VLOOKUP($A14,'[1]STYLE NAMES'!$B:$O,14,FALSE) -> 4 MEVSİM BİNİCİ ÇORABI 3'LÜ PAKET | D14: 39.9 | E14: =ROUNDDOWN(+D14*EURKUR,-1) -> 2190 | F14: =+D14*$F$1 -> 45.885 | G14: =+VLOOKUP($A14,'[1]STYLE NAMES'!$B:$O,2,FALSE) -> 4 SEASON RIDING SOCKS 3 PACK BUNDLE
... A91: MARCELA | B91: =+VLOOKUP($A91,'[1]STYLE NAMES'!$B:$O,4,FALSE) -> RIDER | C91: =+VLOOKUP($A91,'[1]STYLE NAMES'!$B:$O,14,FALSE) -> KADIN ÖN PANELLİ YARIŞMA GÖMLEĞİ | D91: 129.9 | E91: =ROUNDDOWN(+D91*EURKUR,-1) -> 7140 | F91: =+D91*$F$1 -> 149.385 | G91: =+VLOOKUP($A91,'[1]STYLE NAMES'!$B:$O,2,FALSE) -> WOMEN'S COMPETITION SHIRT BIB PANEL
A92: VENETA | B92: =+VLOOKUP(A92,'[1]STYLE NAMES'!$B:$O,4,FALSE) -> RIDER | C92: =+VLOOKUP($A92,'[1]STYLE NAMES'!$B:$O,14,FALSE) -> KADIN OVERSIZE CASUAL GÖMLEK | D92: 129.9 | E92: =ROUNDDOWN(+D92*EURKUR,-1) -> 7140 | F92: =+D92*$F$1 -> 149.385 | G92: =+VLOOKUP($A92,'[1]STYLE NAMES'!$B:$O,2,FALSE) -> WOMEN'S OVERSIZE CASUAL SHIRT
A93: MILANO | B93: =+VLOOKUP(A93,'[1]STYLE NAMES'!$B:$O,4,FALSE) -> RIDER | C93: =+VLOOKUP($A93,'[1]STYLE NAMES'!$B:$O,14,FALSE) -> ERKEK UZUN KOL YARIŞMA GÖMLEĞİ - AÇIK YAKA | D93: 129.9 | E93: =ROUNDDOWN(+D93*EURKUR,-1) -> 7140 | F93: =+D93*$F$1 -> 149.385 | G93: =+VLOOKUP($A93,'[1]STYLE NAMES'!$B:$O,2,FALSE) -> MEN'S COMPETITION SHIRT LONG SLEEVE SPREAD COLLAR
A94: NAPOLI | B94: =+VLOOKUP(A94,'[1]STYLE NAMES'!$B:$O,4,FALSE) -> RIDER | C94: =+VLOOKUP($A94,'[1]STYLE NAMES'!$B:$O,14,FALSE) -> ERKEK UZUN KOL YARIŞMA GÖMLEĞİ - AÇIK YAKA | D94: 129.9 | E94: =ROUNDDOWN(+D94*EURKUR,-1) -> 7140 | F94: =+D94*$F$1 -> 149.385 | G94: =+VLOOKUP($A94,'[1]STYLE NAMES'!$B:$O,2,FALSE) -> MEN'S COMPETITION SHIRT LONG SLEEVE SPREAD COLLAR
A95: ATLANTIS | B95: =+VLOOKUP(A95,'[1]STYLE NAMES'!$B:$O,4,FALSE) -> RIDER | C95: =+VLOOKUP($A95,'[1]STYLE NAMES'!$B:$O,14,FALSE) -> ÇOCUK UNISEX BİNİCİ PANTOLONU | D95: 159.9 | E95: =ROUNDDOWN(+D95*EURKUR,-1) -> 8790 | F95: =+D95*$F$1 -> 183.885 | G95: =+VLOOKUP($A95,'[1]STYLE NAMES'!$B:$O,2,FALSE) -> KID'S UNISEX KNEE GRIP PRO BREECHES
A96: ATLANTIS-W | B96: =+VLOOKUP(A96,'[1]STYLE NAMES'!$B:$O,4,FALSE) -> RIDER | C96: =+VLOOKUP($A96,'[1]STYLE NAMES'!$B:$O,14,FALSE) -> KIŞLIK ÇOCUK UNISEX BİNİCİ PANTOLONU | D96: 169.9 | E96: =ROUNDDOWN(+D96*EURKUR,-1) -> 9340 | F96: =+D96*$F$1 -> 195.385 | G96: =+VLOOKUP($A96,'[1]STYLE NAMES'!$B:$O,2,FALSE) -> KID'S UNISEX KNEE GRIP PRO WINTER BREECHES
A97: MONTERREY | B97: =+VLOOKUP(A97,'[1]STYLE NAMES'!$B:$O,4,FALSE) -> HORSE | C97: =+VLOOKUP($A97,'[1]STYLE NAMES'!$B:$O,14,FALSE) -> MEVSİMLİK AHIR BLANKETİ | D97: 189.9 | E97: =ROUNDDOWN(+D97*EURKUR,-1) -> 10440 | F97: =+D97*$F$1 -> 218.385 | G97: =+VLOOKUP($A97,'[1]STYLE NAMES'!$B:$O,2,FALSE) -> SEASONAL STABLE RUG
A98: MONTERREY-P | B98: =+VLOOKUP(A98,'[1]STYLE NAMES'!$B:$O,4,FALSE) -> HORSE | C98: =+VLOOKUP($A98,'[1]STYLE NAMES'!$B:$O,14,FALSE) -> MEVSİMLİK PONY AHIR BLANKETİ | D98: 189.9 | E98: =ROUNDDOWN(+D98*EURKUR,-1) -> 10440 | F98: =+D98*$F$1 -> 218.385 | G98: =+VLOOKUP($A98,'[1]STYLE NAMES'!$B:$O,2,FALSE) -> SEASONAL STABLE RUG
A99: ALEA | B99: =+VLOOKUP(A99,'[1]STYLE NAMES'!$B:$O,4,FALSE) -> RIDER | C99: =+VLOOKUP($A99,'[1]STYLE NAMES'!$B:$O,14,FALSE) -> KADIN PRO BİNİCİ PANTOLONU | D99: 219.9 | E99: =ROUNDDOWN(+D99*EURKUR,-1) -> 12090 | F99: =+D99*$F$1 -> 252.885 | G99: =+VLOOKUP($A99,'[1]STYLE NAMES'!$B:$O,2,FALSE) -> WOMEN'S KNEE GRIP PRO BREECHES
A100: ALEA-W | B100: =+VLOOKUP(A100,'[1]STYLE NAMES'!$B:$O,4,FALSE) -> RIDER | C100: =+VLOOKUP($A100,'[1]STYLE NAMES'!$B:$O,14,FALSE) -> KIŞLIK KADIN PRO BİNİCİ PANTOLONU | D100: 229.9 | E100: =ROUNDDOWN(+D100*EURKUR,-1) -> 12640 | F100: =+D100*$F$1 -> 264.385 | G100: =+VLOOKUP($A100,'[1]STYLE NAMES'!$B:$O,2,FALSE) -> WOMEN'S KNEE GRIP PRO WINTER BREECHES
A101: LEONARDO | B101: =+VLOOKUP(A101,'[1]STYLE NAMES'!$B:$O,4,FALSE) -> RIDER | C101: =+VLOOKUP($A101,'[1]STYLE NAMES'!$B:$O,14,FALSE) -> ERKEK PRO BİNİCİ PANTOLONU | D101: 219.9 | E101: =ROUNDDOWN(+D101*EURKUR,-1) -> 12090 | F101: =+D101*$F$1 -> 252.885 | G101: =+VLOOKUP($A101,'[1]STYLE NAMES'!$B:$O,2,FALSE) -> MEN'S KNEE GRIP PRO BREECHES
A102: LEONARDO-W | B102: =+VLOOKUP(A102,'[1]STYLE NAMES'!$B:$O,4,FALSE) -> RIDER | C102: =+VLOOKUP($A102,'[1]STYLE NAMES'!$B:$O,14,FALSE) -> KIŞLIK ERKEK PRO BİNİCİ PANTOLONU | D102: 229.9 | E102: =ROUNDDOWN(+D102*EURKUR,-1) -> 12640 | F102: =+D102*$F$1 -> 264.385 | G102: =+VLOOKUP($A102,'[1]STYLE NAMES'!$B:$O,2,FALSE) -> MEN'S KNEE GRIP PRO WINTER BREECHES
A103: ALASKA | B103: =+VLOOKUP(A103,'[1]STYLE NAMES'!$B:$O,4,FALSE) -> HORSE | C103: =+VLOOKUP($A103,'[1]STYLE NAMES'!$B:$O,14,FALSE) -> KIŞLIK AHIR BLANKETİ | D103: 249.9 | E103: =ROUNDDOWN(+D103*EURKUR,-1) -> 13740 | F103: =+D103*$F$1 -> 287.385 | G103: =+VLOOKUP($A103,'[1]STYLE NAMES'!$B:$O,2,FALSE) -> WINTER STABLE RUG
... A108: AREZZO-TBF | B108: =+VLOOKUP(A108,'[1]STYLE NAMES'!$B:$O,4,FALSE) -> RIDER | C108: =+VLOOKUP($A108,'[1]STYLE NAMES'!$B:$O,14,FALSE) -> ERKEK PRO YARIŞMA CEKETİ X TEAM TÜRKİYE | D108: 499.9 | E108: =ROUNDDOWN(+D108*EURKUR,-1) -> 27490 | F108: =+D108*$F$1 -> 574.885 | G108: =+VLOOKUP($A108,'[1]STYLE NAMES'!$B:$O,2,FALSE) -> MEN'S PRO COMPETITION JACKET X TEAM TÜRKİYE
A109: GORLA MINORE-TBF | B109: RIDER | C109: =+VLOOKUP($A109,'[1]STYLE NAMES'!$B:$O,14,FALSE) -> KADIN PRO YARIŞMA CEKETİ X TEAM TÜRKİYE | D109: 499.9 | E109: =ROUNDDOWN(+D109*EURKUR,-1) -> 27490 | F109: =+D109*$F$1 -> 574.885 | G109: =+VLOOKUP($A109,'[1]STYLE NAMES'!$B:$O,2,FALSE) -> WOMEN'S PRO COMPETITION JACKET X TEAM TÜRKİYE
A112: TECH EYERALTLARI | B112: isim ver | C112: 89
A113: NATURAL EYER ALTLARI | C113: 79
A114: SİTEDE MARBELLA PATH KONTROL ET, CAT. CASUAL SHIRTS OLARAK DEĞİŞTİĞİ İÇİN KODE DEĞİŞTİ
A115: TECH EYERALTI + KULAKLIK COMBO
A116: ÜRÜN AÇIKLAMALARINA SECOND SKIN, BASE LAYER, STRASS VS EKLE
A118: eski dokuma kravatları tbf ye ver, çin de yeni kravat yaptır
A119: ottawa isim değiştşir
A120: tech series genel isim ver
A121: MENDERISO ismini MILANO ile değiştirdim
A122: ASPEN-STRASS AÇILACAK | B122: ÜRÜN KODU VE TANIMLAMALARI AÇ

Sheet MASTER PRICE LIST
B2: Cavalier SanMarco MASTER Fiyat Listesi (sadece yönetim kullanımı içindir)
C8: =+'CSM PRICE LIST 26.1.3'!B1 -> v.26.1.3 | D8: =+'CSM PRICE LIST 26.1.3'!C1 -> Valid Through: 01.01.26 - 31.06.26 | E8: 4 | F8: 5 | G8: 6 | H8: 7 | I8: 8 | J8: 9 | K8: 10
B9: MODEL ADI | C9: KATEGORİ | D9: ÜRÜN ADI | E9: € PRICE | F9: TAVSİYE EDİLEN PERAKENDE SATIŞ FİYATI | G9: ÖZEL GÜNLER İNDİRİMİ K.KARTI | H9: ÖZEL GÜNLER İNDİRİMİ NAKİT&IBAN | I9: FAMILY & FRIENDS TL | J9: HOCALAR VE YK ÖZEL İSKONTO ALIŞ FİYATI | K9: YAKLAŞIK MALİYET (YK ŞAHSİ ALIŞLAR)
B10: MODEL NAME | C10: CATEGORY | D10: PRODUCT NAME | E10: LIST PRICE | F10: LISTE FİYATI KDV DAHİL | G10: %20 İNDİRİM | H10: %30 İNDİRİM | I10: %40 İNDİRİM | J10: %50 İNDİRİM | K10: %70 İNDİRİM
B11: FERNANDO | C11: =+VLOOKUP($B11,'CSM PRICE LIST 26.1.3'!$A$2:$E$110,2,FALSE) -> ACCESSORIES | D11: =+VLOOKUP($B11,'CSM PRICE LIST 26.1.3'!$A$2:$E$110,3,FALSE) -> ANAHTARLIK | E11: =+VLOOKUP($B11,'CSM PRICE LIST 26.1.3'!$A$2:$E$110,4,FALSE) -> 12.9 | F11: =+VLOOKUP($B11,'CSM PRICE LIST 26.1.3'!$A$2:$E$110,5,FALSE) -> 700 | G11: =+ROUNDDOWN(F11*0.8,-2) -> 500 | H11: =+ROUNDDOWN(F11*0.7,-2) -> 400 | I11: =+ROUNDDOWN(F11*0.6,-1) -> 420 | J11: =ROUNDUP(+F11*0.5,0) -> 350 | K11: =ROUNDUP(+F11*0.3,-1) -> 210
B12: NANDO | C12: =+VLOOKUP($B12,'CSM PRICE LIST 26.1.3'!$A$2:$E$110,2,FALSE) -> ACCESSORIES | D12: =+VLOOKUP($B12,'CSM PRICE LIST 26.1.3'!$A$2:$E$110,3,FALSE) -> İSİM KÜNYESİ | E12: =+VLOOKUP($B12,'CSM PRICE LIST 26.1.3'!$A$2:$E$110,4,FALSE) -> 12.9 | F12: =+VLOOKUP($B12,'CSM PRICE LIST 26.1.3'!$A$2:$E$110,5,FALSE) -> 700 | G12: =+ROUNDDOWN(F12*0.8,-2) -> 500 | H12: =+ROUNDDOWN(F12*0.7,-2) -> 400 | I12: =+ROUNDDOWN(F12*0.6,-1) -> 420 | J12: =ROUNDUP(+F12*0.5,0) -> 350 | K12: =ROUNDUP(+F12*0.3,-1) -> 210
B13: BANDANA | C13: =+VLOOKUP($B13,'CSM PRICE LIST 26.1.3'!$A$2:$E$110,2,FALSE) -> ACCESSORIES | D13: =+VLOOKUP($B13,'CSM PRICE LIST 26.1.3'!$A$2:$E$110,3,FALSE) -> BANDANA | E13: =+VLOOKUP($B13,'CSM PRICE LIST 26.1.3'!$A$2:$E$110,4,FALSE) -> 12.9 | F13: =+VLOOKUP($B13,'CSM PRICE LIST 26.1.3'!$A$2:$E$110,5,FALSE) -> 700 | G13: =+ROUNDDOWN(F13*0.8,-2) -> 500 | H13: =+ROUNDDOWN(F13*0.7,-2) -> 400 | I13: =+ROUNDDOWN(F13*0.6,-1) -> 420 | J13: =ROUNDUP(+F13*0.5,0) -> 350 | K13: =ROUNDUP(+F13*0.3,-1) -> 210
B14: CAPE TOWN | C14: =+VLOOKUP($B14,'CSM PRICE LIST 26.1.3'!$A$2:$E$110,2,FALSE) -> ACCESSORIES | D14: =+VLOOKUP($B14,'CSM PRICE LIST 26.1.3'!$A$2:$E$110,3,FALSE) -> KEP ŞAPKA | E14: =+VLOOKUP($B14,'CSM PRICE LIST 26.1.3'!$A$2:$E$110,4,FALSE) -> 29.9 | F14: =+VLOOKUP($B14,'CSM PRICE LIST 26.1.3'!$A$2:$E$110,5,FALSE) -> 1640 | G14: =+ROUNDDOWN(F14*0.8,-2) -> 1300 | H14: =+ROUNDDOWN(F14*0.7,-2) -> 1100 | I14: =+ROUNDDOWN(F14*0.6,-1) -> 980 | J14: =ROUNDUP(+F14*0.5,0) -> 820 | K14: =ROUNDUP(+F14*0.3,-1) -> 500
B15: OTTAWA | C15: =+VLOOKUP($B15,'CSM PRICE LIST 26.1.3'!$A$2:$E$110,2,FALSE) -> ACCESSORIES | D15: =+VLOOKUP($B15,'CSM PRICE LIST 26.1.3'!$A$2:$E$110,3,FALSE) -> BERE ŞAPKA | E15: =+VLOOKUP($B15,'CSM PRICE LIST 26.1.3'!$A$2:$E$110,4,FALSE) -> 29.9 | F15: =+VLOOKUP($B15,'CSM PRICE LIST 26.1.3'!$A$2:$E$110,5,FALSE) -> 1640 | G15: =+ROUNDDOWN(F15*0.8,-2) -> 1300 | H15: =+ROUNDDOWN(F15*0.7,-2) -> 1100 | I15: =+ROUNDDOWN(F15*0.6,-1) -> 980 | J15: =ROUNDUP(+F15*0.5,0) -> 820 | K15: =ROUNDUP(+F15*0.3,-1) -> 500
B16: CAPRI-3XB | C16: =+VLOOKUP($B16,'CSM PRICE LIST 26.1.3'!$A$2:$E$110,2,FALSE) -> ACCESSORIES | D16: =+VLOOKUP($B16,'CSM PRICE LIST 26.1.3'!$A$2:$E$110,3,FALSE) -> YAZLIK BİNİCİ ÇORABI 3'LÜ PAKET | E16: =+VLOOKUP($B16,'CSM PRICE LIST 26.1.3'!$A$2:$E$110,4,FALSE) -> 34.9 | F16: =+VLOOKUP($B16,'CSM PRICE LIST 26.1.3'!$A$2:$E$110,5,FALSE) -> 1910 | G16: =+ROUNDDOWN(F16*0.8,-2) -> 1500 | H16: =+ROUNDDOWN(F16*0.7,-2) -> 1300 | I16: =+ROUNDDOWN(F16*0.6,-1) -> 1140 | J16: =ROUNDUP(+F16*0.5,0) -> 955 | K16: =ROUNDUP(+F16*0.3,-1) -> 580
B17: LAZIO-3XB | C17: =+VLOOKUP($B17,'CSM PRICE LIST 26.1.3'!$A$2:$E$110,2,FALSE) -> ACCESSORIES | D17: =+VLOOKUP($B17,'CSM PRICE LIST 26.1.3'!$A$2:$E$110,3,FALSE) -> GEO 4 MEVSİM BİNİCİ ÇORABI 3'LÜ PAKET | E17: =+VLOOKUP($B17,'CSM PRICE LIST 26.1.3'!$A$2:$E$110,4,FALSE) -> 34.9 | F17: =+VLOOKUP($B17,'CSM PRICE LIST 26.1.3'!$A$2:$E$110,5,FALSE) -> 1910 | G17: =+ROUNDDOWN(F17*0.8,-2) -> 1500 | H17: =+ROUNDDOWN(F17*0.7,-2) -> 1300 | I17: =+ROUNDDOWN(F17*0.6,-1) -> 1140 | J17: =ROUNDUP(+F17*0.5,0) -> 955 | K17: =ROUNDUP(+F17*0.3,-1) -> 580
B18: LUCCA-3XB | C18: =+VLOOKUP($B18,'CSM PRICE LIST 26.1.3'!$A$2:$E$110,2,FALSE) -> ACCESSORIES | D18: =+VLOOKUP($B18,'CSM PRICE LIST 26.1.3'!$A$2:$E$110,3,FALSE) -> ÇOCUK BİNİCİ ÇORABI 3'LÜ PAKET | E18: =+VLOOKUP($B18,'CSM PRICE LIST 26.1.3'!$A$2:$E$110,4,FALSE) -> 34.9 | F18: =+VLOOKUP($B18,'CSM PRICE LIST 26.1.3'!$A$2:$E$110,5,FALSE) -> 1910 | G18: =+ROUNDDOWN(F18*0.8,-2) -> 1500 | H18: =+ROUNDDOWN(F18*0.7,-2) -> 1300 | I18: =+ROUNDDOWN(F18*0.6,-1) -> 1140 | J18: =ROUNDUP(+F18*0.5,0) -> 955 | K18: =ROUNDUP(+F18*0.3,-1) -> 580
B19: CAMBRIDGE | C19: =+VLOOKUP($B19,'CSM PRICE LIST 26.1.3'!$A$2:$E$110,2,FALSE) -> ACCESSORIES | D19: =+VLOOKUP($B19,'CSM PRICE LIST 26.1.3'!$A$2:$E$110,3,FALSE) -> YARIŞMA KRAVATI | E19: =+VLOOKUP($B19,'CSM PRICE LIST 26.1.3'!$A$2:$E$110,4,FALSE) -> 39.9 | F19: =+VLOOKUP($B19,'CSM PRICE LIST 26.1.3'!$A$2:$E$110,5,FALSE) -> 2190 | G19: =+ROUNDDOWN(F19*0.8,-2) -> 1700 | H19: =+ROUNDDOWN(F19*0.7,-2) -> 1500 | I19: =+ROUNDDOWN(F19*0.6,-1) -> 1310 | J19: =ROUNDUP(+F19*0.5,0) -> 1095 | K19: =ROUNDUP(+F19*0.3,-1) -> 660
B20: FONDI-3XB | C20: =+VLOOKUP($B20,'CSM PRICE LIST 26.1.3'!$A$2:$E$110,2,FALSE) -> ACCESSORIES | D20: =+VLOOKUP($B20,'CSM PRICE LIST 26.1.3'!$A$2:$E$110,3,FALSE) -> 4 MEVSİM BİNİCİ ÇORABI 3'LÜ PAKET | E20: =+VLOOKUP($B20,'CSM PRICE LIST 26.1.3'!$A$2:$E$110,4,FALSE) -> 39.9 | F20: =+VLOOKUP($B20,'CSM PRICE LIST 26.1.3'!$A$2:$E$110,5,FALSE) -> 2190 | G20: =+ROUNDDOWN(F20*0.8,-2) -> 1700 | H20: =+ROUNDDOWN(F20*0.7,-2) -> 1500 | I20: =+ROUNDDOWN(F20*0.6,-1) -> 1310 | J20: =ROUNDUP(+F20*0.5,0) -> 1095 | K20: =ROUNDUP(+F20*0.3,-1) -> 660
B21: OXFORD | C21: =+VLOOKUP($B21,'CSM PRICE LIST 26.1.3'!$A$2:$E$110,2,FALSE) -> ACCESSORIES | D21: =+VLOOKUP($B21,'CSM PRICE LIST 26.1.3'!$A$2:$E$110,3,FALSE) -> ÖRME YARIŞMA KRAVATI | E21: =+VLOOKUP($B21,'CSM PRICE LIST 26.1.3'!$A$2:$E$110,4,FALSE) -> 39.9 | F21: =+VLOOKUP($B21,'CSM PRICE LIST 26.1.3'!$A$2:$E$110,5,FALSE) -> 2190 | G21: =+ROUNDDOWN(F21*0.8,-2) -> 1700 | H21: =+ROUNDDOWN(F21*0.7,-2) -> 1500 | I21: =+ROUNDDOWN(F21*0.6,-1) -> 1310 | J21: =ROUNDUP(+F21*0.5,0) -> 1095 | K21: =ROUNDUP(+F21*0.3,-1) -> 660
B22: ROMA-3XB | C22: =+VLOOKUP($B22,'CSM PRICE LIST 26.1.3'!$A$2:$E$110,2,FALSE) -> ACCESSORIES | D22: =+VLOOKUP($B22,'CSM PRICE LIST 26.1.3'!$A$2:$E$110,3,FALSE) -> 4 MEVSİM BİNİCİ ÇORABI 3'LÜ PAKET | E22: =+VLOOKUP($B22,'CSM PRICE LIST 26.1.3'!$A$2:$E$110,4,FALSE) -> 39.9 | F22: =+VLOOKUP($B22,'CSM PRICE LIST 26.1.3'!$A$2:$E$110,5,FALSE) -> 2190 | G22: =+ROUNDDOWN(F22*0.8,-2) -> 1700 | H22: =+ROUNDDOWN(F22*0.7,-2) -> 1500 | I22: =+ROUNDDOWN(F22*0.6,-1) -> 1310 | J22: =ROUNDUP(+F22*0.5,0) -> 1095 | K22: =ROUNDUP(+F22*0.3,-1) -> 660
... B117: GORLA MINORE-TBF | C117: =+VLOOKUP($B117,'CSM PRICE LIST 26.1.3'!$A$2:$E$110,2,FALSE) -> RIDER | D117: =+VLOOKUP($B117,'CSM PRICE LIST 26.1.3'!$A$2:$E$110,3,FALSE) -> KADIN PRO YARIŞMA CEKETİ X TEAM TÜRKİYE | E117: =+VLOOKUP($B117,'CSM PRICE LIST 26.1.3'!$A$2:$E$110,4,FALSE) -> 499.9 | F117: =+VLOOKUP($B117,'CSM PRICE LIST 26.1.3'!$A$2:$E$110,5,FALSE) -> 27490 | G117: =+ROUNDDOWN(F117*0.8,-2) -> 21900 | H117: =+ROUNDDOWN(F117*0.7,-2) -> 19200 | I117: =+ROUNDDOWN(F117*0.6,-1) -> 16490 | J117: =ROUNDUP(+F117*0.5,0) -> 13745 | K117: =ROUNDUP(+F117*0.3,-1) -> 8250
B119: NOT: 7-8-9-10 numaralı sütunlar, yani nakit/IBAN ödemeli extra indirimlerde KDV dahil değildir

Sheet PERAKENDE FİYAT LİSTESİ FULL
B2: Cavalier SanMarco PERAKENDE Fiyat Listesi
C8: =+'CSM PRICE LIST 26.1.3'!B1 -> v.26.1.3 | D8: =+'CSM PRICE LIST 26.1.3'!C1 -> Valid Through: 01.01.26 - 31.06.26 | E8: 4 | F8: 5 | G8: 6 | H8: 7
B9: MODEL ADI | C9: KATEGORİ | D9: ÜRÜN ADI | E9: € PRICE | F9: TAVSİYE EDİLEN PERAKENDE SATIŞ FİYATI | G9: ÖZEL GÜNLER İNDİRİMİ K.KARTI | H9: ÖZEL GÜNLER İNDİRİMİ NAKİT&IBAN
B10: MODEL NAME | C10: CATEGORY | D10: PRODUCT NAME | E10: LIST PRICE | F10: LİSTE FİYATI - KDV DAHİL | G10: 0.2 | H10: 0.3
B11: FERNANDO | C11: =+VLOOKUP($B11,'CSM PRICE LIST 26.1.3'!$A$2:$E$110,2,FALSE) -> ACCESSORIES | D11: =+VLOOKUP($B11,'CSM PRICE LIST 26.1.3'!$A$2:$E$110,3,FALSE) -> ANAHTARLIK | E11: =+VLOOKUP($B11,'MASTER PRICE LIST'!$B$9:$K$119,4,FALSE) -> 12.9 | F11: =+VLOOKUP($B11,'MASTER PRICE LIST'!$B$9:$K$119,5,FALSE) -> 700 | G11: =+VLOOKUP($B11,'MASTER PRICE LIST'!$B$9:$K$119,6,FALSE) -> 500 | H11: =+VLOOKUP($B11,'MASTER PRICE LIST'!$B$9:$K$119,7,FALSE) -> 400
B12: NANDO | C12: =+VLOOKUP($B12,'CSM PRICE LIST 26.1.3'!$A$2:$E$110,2,FALSE) -> ACCESSORIES | D12: =+VLOOKUP($B12,'CSM PRICE LIST 26.1.3'!$A$2:$E$110,3,FALSE) -> İSİM KÜNYESİ | E12: =+VLOOKUP($B12,'MASTER PRICE LIST'!$B$9:$K$119,4,FALSE) -> 12.9 | F12: =+VLOOKUP($B12,'MASTER PRICE LIST'!$B$9:$K$119,5,FALSE) -> 700 | G12: =+VLOOKUP($B12,'MASTER PRICE LIST'!$B$9:$K$119,6,FALSE) -> 500 | H12: =+VLOOKUP($B12,'MASTER PRICE LIST'!$B$9:$K$119,7,FALSE) -> 400
B13: BANDANA | C13: =+VLOOKUP($B13,'CSM PRICE LIST 26.1.3'!$A$2:$E$110,2,FALSE) -> ACCESSORIES | D13: =+VLOOKUP($B13,'CSM PRICE LIST 26.1.3'!$A$2:$E$110,3,FALSE) -> BANDANA | E13: =+VLOOKUP($B13,'MASTER PRICE LIST'!$B$9:$K$119,4,FALSE) -> 12.9 | F13: =+VLOOKUP($B13,'MASTER PRICE LIST'!$B$9:$K$119,5,FALSE) -> 700 | G13: =+VLOOKUP($B13,'MASTER PRICE LIST'!$B$9:$K$119,6,FALSE) -> 500 | H13: =+VLOOKUP($B13,'MASTER PRICE LIST'!$B$9:$K$119,7,FALSE) -> 400
B14: CAPE TOWN | C14: =+VLOOKUP($B14,'CSM PRICE LIST 26.1.3'!$A$2:$E$110,2,FALSE) -> ACCESSORIES | D14: =+VLOOKUP($B14,'CSM PRICE LIST 26.1.3'!$A$2:$E$110,3,FALSE) -> KEP ŞAPKA | E14: =+VLOOKUP($B14,'MASTER PRICE LIST'!$B$9:$K$119,4,FALSE) -> 29.9 | F14: =+VLOOKUP($B14,'MASTER PRICE LIST'!$B$9:$K$119,5,FALSE) -> 1640 | G14: =+VLOOKUP($B14,'MASTER PRICE LIST'!$B$9:$K$119,6,FALSE) -> 1300 | H14: =+VLOOKUP($B14,'MASTER PRICE LIST'!$B$9:$K$119,7,FALSE) -> 1100
B15: OTTAWA | C15: =+VLOOKUP($B15,'CSM PRICE LIST 26.1.3'!$A$2:$E$110,2,FALSE) -> ACCESSORIES | D15: =+VLOOKUP($B15,'CSM PRICE LIST 26.1.3'!$A$2:$E$110,3,FALSE) -> BERE ŞAPKA | E15: =+VLOOKUP($B15,'MASTER PRICE LIST'!$B$9:$K$119,4,FALSE) -> 29.9 | F15: =+VLOOKUP($B15,'MASTER PRICE LIST'!$B$9:$K$119,5,FALSE) -> 1640 | G15: =+VLOOKUP($B15,'MASTER PRICE LIST'!$B$9:$K$119,6,FALSE) -> 1300 | H15: =+VLOOKUP($B15,'MASTER PRICE LIST'!$B$9:$K$119,7,FALSE) -> 1100
B16: CAPRI-3XB | C16: =+VLOOKUP($B16,'CSM PRICE LIST 26.1.3'!$A$2:$E$110,2,FALSE) -> ACCESSORIES | D16: =+VLOOKUP($B16,'CSM PRICE LIST 26.1.3'!$A$2:$E$110,3,FALSE) -> YAZLIK BİNİCİ ÇORABI 3'LÜ PAKET | E16: =+VLOOKUP($B16,'MASTER PRICE LIST'!$B$9:$K$119,4,FALSE) -> 34.9 | F16: =+VLOOKUP($B16,'MASTER PRICE LIST'!$B$9:$K$119,5,FALSE) -> 1910 | G16: =+VLOOKUP($B16,'MASTER PRICE LIST'!$B$9:$K$119,6,FALSE) -> 1500 | H16: =+VLOOKUP($B16,'MASTER PRICE LIST'!$B$9:$K$119,7,FALSE) -> 1300
B17: LAZIO-3XB | C17: =+VLOOKUP($B17,'CSM PRICE LIST 26.1.3'!$A$2:$E$110,2,FALSE) -> ACCESSORIES | D17: =+VLOOKUP($B17,'CSM PRICE LIST 26.1.3'!$A$2:$E$110,3,FALSE) -> GEO 4 MEVSİM BİNİCİ ÇORABI 3'LÜ PAKET | E17: =+VLOOKUP($B17,'MASTER PRICE LIST'!$B$9:$K$119,4,FALSE) -> 34.9 | F17: =+VLOOKUP($B17,'MASTER PRICE LIST'!$B$9:$K$119,5,FALSE) -> 1910 | G17: =+VLOOKUP($B17,'MASTER PRICE LIST'!$B$9:$K$119,6,FALSE) -> 1500 | H17: =+VLOOKUP($B17,'MASTER PRICE LIST'!$B$9:$K$119,7,FALSE) -> 1300
B18: LUCCA-3XB | C18: =+VLOOKUP($B18,'CSM PRICE LIST 26.1.3'!$A$2:$E$110,2,FALSE) -> ACCESSORIES | D18: =+VLOOKUP($B18,'CSM PRICE LIST 26.1.3'!$A$2:$E$110,3,FALSE) -> ÇOCUK BİNİCİ ÇORABI 3'LÜ PAKET | E18: =+VLOOKUP($B18,'MASTER PRICE LIST'!$B$9:$K$119,4,FALSE) -> 34.9 | F18: =+VLOOKUP($B18,'MASTER PRICE LIST'!$B$9:$K$119,5,FALSE) -> 1910 | G18: =+VLOOKUP($B18,'MASTER PRICE LIST'!$B$9:$K$119,6,FALSE) -> 1500 | H18: =+VLOOKUP($B18,'MASTER PRICE LIST'!$B$9:$K$119,7,FALSE) -> 1300
B19: CAMBRIDGE | C19: =+VLOOKUP($B19,'CSM PRICE LIST 26.1.3'!$A$2:$E$110,2,FALSE) -> ACCESSORIES | D19: =+VLOOKUP($B19,'CSM PRICE LIST 26.1.3'!$A$2:$E$110,3,FALSE) -> YARIŞMA KRAVATI | E19: =+VLOOKUP($B19,'MASTER PRICE LIST'!$B$9:$K$119,4,FALSE) -> 39.9 | F19: =+VLOOKUP($B19,'MASTER PRICE LIST'!$B$9:$K$119,5,FALSE) -> 2190 | G19: =+VLOOKUP($B19,'MASTER PRICE LIST'!$B$9:$K$119,6,FALSE) -> 1700 | H19: =+VLOOKUP($B19,'MASTER PRICE LIST'!$B$9:$K$119,7,FALSE) -> 1500
B20: FONDI-3XB | C20: =+VLOOKUP($B20,'CSM PRICE LIST 26.1.3'!$A$2:$E$110,2,FALSE) -> ACCESSORIES | D20: =+VLOOKUP($B20,'CSM PRICE LIST 26.1.3'!$A$2:$E$110,3,FALSE) -> 4 MEVSİM BİNİCİ ÇORABI 3'LÜ PAKET | E20: =+VLOOKUP($B20,'MASTER PRICE LIST'!$B$9:$K$119,4,FALSE) -> 39.9 | F20: =+VLOOKUP($B20,'MASTER PRICE LIST'!$B$9:$K$119,5,FALSE) -> 2190 | G20: =+VLOOKUP($B20,'MASTER PRICE LIST'!$B$9:$K$119,6,FALSE) -> 1700 | H20: =+VLOOKUP($B20,'MASTER PRICE LIST'!$B$9:$K$119,7,FALSE) -> 1500
B21: OXFORD | C21: =+VLOOKUP($B21,'CSM PRICE LIST 26.1.3'!$A$2:$E$110,2,FALSE) -> ACCESSORIES | D21: =+VLOOKUP($B21,'CSM PRICE LIST 26.1.3'!$A$2:$E$110,3,FALSE) -> ÖRME YARIŞMA KRAVATI | E21: =+VLOOKUP($B21,'MASTER PRICE LIST'!$B$9:$K$119,4,FALSE) -> 39.9 | F21: =+VLOOKUP($B21,'MASTER PRICE LIST'!$B$9:$K$119,5,FALSE) -> 2190 | G21: =+VLOOKUP($B21,'MASTER PRICE LIST'!$B$9:$K$119,6,FALSE) -> 1700 | H21: =+VLOOKUP($B21,'MASTER PRICE LIST'!$B$9:$K$119,7,FALSE) -> 1500
B22: ROMA-3XB | C22: =+VLOOKUP($B22,'CSM PRICE LIST 26.1.3'!$A$2:$E$110,2,FALSE) -> ACCESSORIES | D22: =+VLOOKUP($B22,'CSM PRICE LIST 26.1.3'!$A$2:$E$110,3,FALSE) -> 4 MEVSİM BİNİCİ ÇORABI 3'LÜ PAKET | E22: =+VLOOKUP($B22,'MASTER PRICE LIST'!$B$9:$K$119,4,FALSE) -> 39.9 | F22: =+VLOOKUP($B22,'MASTER PRICE LIST'!$B$9:$K$119,5,FALSE) -> 2190 | G22: =+VLOOKUP($B22,'MASTER PRICE LIST'!$B$9:$K$119,6,FALSE) -> 1700 | H22: =+VLOOKUP($B22,'MASTER PRICE LIST'!$B$9:$K$119,7,FALSE) -> 1500
... B117: GORLA MINORE-TBF | C117: =+VLOOKUP($B117,'CSM PRICE LIST 26.1.3'!$A$2:$E$110,2,FALSE) -> RIDER | D117: =+VLOOKUP($B117,'CSM PRICE LIST 26.1.3'!$A$2:$E$110,3,FALSE) -> KADIN PRO YARIŞMA CEKETİ X TEAM TÜRKİYE | E117: =+VLOOKUP($B117,'MASTER PRICE LIST'!$B$9:$K$119,4,FALSE) -> 499.9 | F117: =+VLOOKUP($B117,'MASTER PRICE LIST'!$B$9:$K$119,5,FALSE) -> 27490 | G117: =+VLOOKUP($B117,'MASTER PRICE LIST'!$B$9:$K$119,6,FALSE) -> 21900 | H117: =+VLOOKUP($B117,'MASTER PRICE LIST'!$B$9:$K$119,7,FALSE) -> 19200

Sheet BAYİ FİYAT LİSTESİ
B2: Cavalier SanMarco BAYİ Fiyat Listesi
C8: =+'CSM PRICE LIST 26.1.3'!B1 -> v.26.1.3 | D8: =+'CSM PRICE LIST 26.1.3'!C1 -> Valid Through: 01.01.26 - 31.06.26 | E8: 4 | F8: 5
B9: MODEL ADI | C9: KATEGORİ | D9: ÜRÜN ADI | E9: € PRICE | F9: TAVSİYE EDİLEN PERAKENDE SATIŞ FİYATI | G9: TOPTAN BAYİ ALIŞ FİYATI | H9: PUBLISH
B10: MODEL NAME | C10: CATEGORY | D10: PRODUCT NAME | E10: LIST PRICE | F10: KDV DAHİL | G10: + KDV OLACAKTIR | H10: ÜRÜN VAR / YOK
B11: FERNANDO | C11: =+VLOOKUP($B11,'CSM PRICE LIST 26.1.3'!$A$2:$E$110,2,FALSE) -> ACCESSORIES | D11: =+VLOOKUP($B11,'CSM PRICE LIST 26.1.3'!$A$2:$E$110,3,FALSE) -> ANAHTARLIK | E11: =+VLOOKUP($B11,'MASTER PRICE LIST'!$B$9:$K$117,4,FALSE) -> 12.9 | F11: =+VLOOKUP($B11,'MASTER PRICE LIST'!$B$9:$K$117,5,FALSE) -> 700 | G11: =+F11*0.5 -> 350 | H11: =+VLOOKUP($B11,'CSM PRICE LIST 26.1.3'!$A:$G,8,FALSE) -> #REF!
B12: NANDO | C12: =+VLOOKUP($B12,'CSM PRICE LIST 26.1.3'!$A$2:$E$110,2,FALSE) -> ACCESSORIES | D12: =+VLOOKUP($B12,'CSM PRICE LIST 26.1.3'!$A$2:$E$110,3,FALSE) -> İSİM KÜNYESİ | E12: =+VLOOKUP($B12,'MASTER PRICE LIST'!$B$9:$K$117,4,FALSE) -> 12.9 | F12: =+VLOOKUP($B12,'MASTER PRICE LIST'!$B$9:$K$117,5,FALSE) -> 700 | G12: =+F12*0.5 -> 350 | H12: =+VLOOKUP($B12,'CSM PRICE LIST 26.1.3'!$A:$G,8,FALSE) -> #REF!
B13: BANDANA | C13: =+VLOOKUP($B13,'CSM PRICE LIST 26.1.3'!$A$2:$E$110,2,FALSE) -> ACCESSORIES | D13: =+VLOOKUP($B13,'CSM PRICE LIST 26.1.3'!$A$2:$E$110,3,FALSE) -> BANDANA | E13: =+VLOOKUP($B13,'MASTER PRICE LIST'!$B$9:$K$117,4,FALSE) -> 12.9 | F13: =+VLOOKUP($B13,'MASTER PRICE LIST'!$B$9:$K$117,5,FALSE) -> 700 | G13: =+F13*0.5 -> 350
B14: CAPE TOWN | C14: =+VLOOKUP($B14,'CSM PRICE LIST 26.1.3'!$A$2:$E$110,2,FALSE) -> ACCESSORIES | D14: =+VLOOKUP($B14,'CSM PRICE LIST 26.1.3'!$A$2:$E$110,3,FALSE) -> KEP ŞAPKA | E14: =+VLOOKUP($B14,'MASTER PRICE LIST'!$B$9:$K$117,4,FALSE) -> 29.9 | F14: =+VLOOKUP($B14,'MASTER PRICE LIST'!$B$9:$K$117,5,FALSE) -> 1640 | G14: =+F14*0.5 -> 820 | H14: =+VLOOKUP($B14,'CSM PRICE LIST 26.1.3'!$A:$G,8,FALSE) -> #REF!
B15: OTTAWA | C15: =+VLOOKUP($B15,'CSM PRICE LIST 26.1.3'!$A$2:$E$110,2,FALSE) -> ACCESSORIES | D15: =+VLOOKUP($B15,'CSM PRICE LIST 26.1.3'!$A$2:$E$110,3,FALSE) -> BERE ŞAPKA | E15: =+VLOOKUP($B15,'MASTER PRICE LIST'!$B$9:$K$117,4,FALSE) -> 29.9 | F15: =+VLOOKUP($B15,'MASTER PRICE LIST'!$B$9:$K$117,5,FALSE) -> 1640 | G15: =+F15*0.5 -> 820 | H15: =+VLOOKUP($B15,'CSM PRICE LIST 26.1.3'!$A:$G,8,FALSE) -> #REF!
B16: CAPRI-3XB | C16: =+VLOOKUP($B16,'CSM PRICE LIST 26.1.3'!$A$2:$E$110,2,FALSE) -> ACCESSORIES | D16: =+VLOOKUP($B16,'CSM PRICE LIST 26.1.3'!$A$2:$E$110,3,FALSE) -> YAZLIK BİNİCİ ÇORABI 3'LÜ PAKET | E16: =+VLOOKUP($B16,'MASTER PRICE LIST'!$B$9:$K$117,4,FALSE) -> 34.9 | F16: =+VLOOKUP($B16,'MASTER PRICE LIST'!$B$9:$K$117,5,FALSE) -> 1910 | G16: =+F16*0.5 -> 955 | H16: =+VLOOKUP($B16,'CSM PRICE LIST 26.1.3'!$A:$G,8,FALSE) -> #REF!
B17: LAZIO-3XB | C17: =+VLOOKUP($B17,'CSM PRICE LIST 26.1.3'!$A$2:$E$110,2,FALSE) -> ACCESSORIES | D17: =+VLOOKUP($B17,'CSM PRICE LIST 26.1.3'!$A$2:$E$110,3,FALSE) -> GEO 4 MEVSİM BİNİCİ ÇORABI 3'LÜ PAKET | E17: =+VLOOKUP($B17,'MASTER PRICE LIST'!$B$9:$K$117,4,FALSE) -> 34.9 | F17: =+VLOOKUP($B17,'MASTER PRICE LIST'!$B$9:$K$117,5,FALSE) -> 1910 | G17: =+F17*0.5 -> 955 | H17: =+VLOOKUP($B17,'CSM PRICE LIST 26.1.3'!$A:$G,8,FALSE) -> #REF!
B18: LUCCA-3XB | C18: =+VLOOKUP($B18,'CSM PRICE LIST 26.1.3'!$A$2:$E$110,2,FALSE) -> ACCESSORIES | D18: =+VLOOKUP($B18,'CSM PRICE LIST 26.1.3'!$A$2:$E$110,3,FALSE) -> ÇOCUK BİNİCİ ÇORABI 3'LÜ PAKET | E18: =+VLOOKUP($B18,'MASTER PRICE LIST'!$B$9:$K$117,4,FALSE) -> 34.9 | F18: =+VLOOKUP($B18,'MASTER PRICE LIST'!$B$9:$K$117,5,FALSE) -> 1910 | G18: =+F18*0.5 -> 955 | H18: =+VLOOKUP($B18,'CSM PRICE LIST 26.1.3'!$A:$G,8,FALSE) -> #REF!
B19: CAMBRIDGE | C19: =+VLOOKUP($B19,'CSM PRICE LIST 26.1.3'!$A$2:$E$110,2,FALSE) -> ACCESSORIES | D19: =+VLOOKUP($B19,'CSM PRICE LIST 26.1.3'!$A$2:$E$110,3,FALSE) -> YARIŞMA KRAVATI | E19: =+VLOOKUP($B19,'MASTER PRICE LIST'!$B$9:$K$117,4,FALSE) -> 39.9 | F19: =+VLOOKUP($B19,'MASTER PRICE LIST'!$B$9:$K$117,5,FALSE) -> 2190 | G19: =+F19*0.5 -> 1095 | H19: =+VLOOKUP($B19,'CSM PRICE LIST 26.1.3'!$A:$G,8,FALSE) -> #REF!
B20: FONDI-3XB | C20: =+VLOOKUP($B20,'CSM PRICE LIST 26.1.3'!$A$2:$E$110,2,FALSE) -> ACCESSORIES | D20: =+VLOOKUP($B20,'CSM PRICE LIST 26.1.3'!$A$2:$E$110,3,FALSE) -> 4 MEVSİM BİNİCİ ÇORABI 3'LÜ PAKET | E20: =+VLOOKUP($B20,'MASTER PRICE LIST'!$B$9:$K$117,4,FALSE) -> 39.9 | F20: =+VLOOKUP($B20,'MASTER PRICE LIST'!$B$9:$K$117,5,FALSE) -> 2190 | G20: =+F20*0.5 -> 1095 | H20: =+VLOOKUP($B20,'CSM PRICE LIST 26.1.3'!$A:$G,8,FALSE) -> #REF!
B21: OXFORD | C21: =+VLOOKUP($B21,'CSM PRICE LIST 26.1.3'!$A$2:$E$110,2,FALSE) -> ACCESSORIES | D21: =+VLOOKUP($B21,'CSM PRICE LIST 26.1.3'!$A$2:$E$110,3,FALSE) -> ÖRME YARIŞMA KRAVATI | E21: =+VLOOKUP($B21,'MASTER PRICE LIST'!$B$9:$K$117,4,FALSE) -> 39.9 | F21: =+VLOOKUP($B21,'MASTER PRICE LIST'!$B$9:$K$117,5,FALSE) -> 2190 | G21: =+F21*0.5 -> 1095
B22: ROMA-3XB | C22: =+VLOOKUP($B22,'CSM PRICE LIST 26.1.3'!$A$2:$E$110,2,FALSE) -> ACCESSORIES | D22: =+VLOOKUP($B22,'CSM PRICE LIST 26.1.3'!$A$2:$E$110,3,FALSE) -> 4 MEVSİM BİNİCİ ÇORABI 3'LÜ PAKET | E22: =+VLOOKUP($B22,'MASTER PRICE LIST'!$B$9:$K$117,4,FALSE) -> 39.9 | F22: =+VLOOKUP($B22,'MASTER PRICE LIST'!$B$9:$K$117,5,FALSE) -> 2190 | G22: =+F22*0.5 -> 1095 | H22: =+VLOOKUP($B22,'CSM PRICE LIST 26.1.3'!$A:$G,8,FALSE) -> #REF!
B23: TORINO-2XB | C23: =+VLOOKUP($B23,'CSM PRICE LIST 26.1.3'!$A$2:$E$110,2,FALSE) -> ACCESSORIES | D23: =+VLOOKUP($B23,'CSM PRICE LIST 26.1.3'!$A$2:$E$110,3,FALSE) -> KIŞLIK BİNİCİ ÇORABI 2'Lİ PAKET | E23: =+VLOOKUP($B23,'MASTER PRICE LIST'!$B$9:$K$117,4,FALSE) -> 39.9 | F23: =+VLOOKUP($B23,'MASTER PRICE LIST'!$B$9:$K$117,5,FALSE) -> 2190 | G23: =+F23*0.5 -> 1095 | H23: =+VLOOKUP($B23,'CSM PRICE LIST 26.1.3'!$A:$G,8,FALSE) -> #REF!
B24: SALVADOR | C24: =+VLOOKUP($B24,'CSM PRICE LIST 26.1.3'!$A$2:$E$110,2,FALSE) -> ACCESSORIES | D24: =+VLOOKUP($B24,'CSM PRICE LIST 26.1.3'!$A$2:$E$110,3,FALSE) -> BOX PERDESİ | E24: =+VLOOKUP($B24,'MASTER PRICE LIST'!$B$9:$K$117,4,FALSE) -> 49.9 | F24: =+VLOOKUP($B24,'MASTER PRICE LIST'!$B$9:$K$117,5,FALSE) -> 2740 | G24: =+F24*0.5 -> 1370 | H24: =+VLOOKUP($B24,'CSM PRICE LIST 26.1.3'!$A:$G,8,FALSE) -> #REF!
B25: SANTINI | C25: =+VLOOKUP($B25,'CSM PRICE LIST 26.1.3'!$A$2:$E$110,2,FALSE) -> ACCESSORIES | D25: =+VLOOKUP($B25,'CSM PRICE LIST 26.1.3'!$A$2:$E$110,3,FALSE) -> ÖRGÜ KEMER | E25: =+VLOOKUP($B25,'MASTER PRICE LIST'!$B$9:$K$117,4,FALSE) -> 49.9 | F25: =+VLOOKUP($B25,'MASTER PRICE LIST'!$B$9:$K$117,5,FALSE) -> 2740 | G25: =+F25*0.5 -> 1370
B26: SANTORINI | C26: =+VLOOKUP($B26,'CSM PRICE LIST 26.1.3'!$A$2:$E$110,2,FALSE) -> ACCESSORIES | D26: =+VLOOKUP($B26,'CSM PRICE LIST 26.1.3'!$A$2:$E$110,3,FALSE) -> ÖRGÜ KEMER | E26: =+VLOOKUP($B26,'MASTER PRICE LIST'!$B$9:$K$117,4,FALSE) -> 49.9 | F26: =+VLOOKUP($B26,'MASTER PRICE LIST'!$B$9:$K$117,5,FALSE) -> 2740 | G26: =+F26*0.5 -> 1370 | H26: =+VLOOKUP($B26,'CSM PRICE LIST 26.1.3'!$A:$G,8,FALSE) -> #REF!
B27: SANTIAGO | C27: =+VLOOKUP($B27,'CSM PRICE LIST 26.1.3'!$A$2:$E$110,2,FALSE) -> ACCESSORIES | D27: =+VLOOKUP($B27,'CSM PRICE LIST 26.1.3'!$A$2:$E$110,3,FALSE) -> ÖRGÜ KEMER | E27: =+VLOOKUP($B27,'MASTER PRICE LIST'!$B$9:$K$117,4,FALSE) -> 59.9 | F27: =+VLOOKUP($B27,'MASTER PRICE LIST'!$B$9:$K$117,5,FALSE) -> 3290 | G27: =+F27*0.5 -> 1645 | H27: =+VLOOKUP($B27,'CSM PRICE LIST 26.1.3'!$A:$G,8,FALSE) -> #REF!
B28: SALERNO | C28: =+VLOOKUP($B28,'CSM PRICE LIST 26.1.3'!$A$2:$E$110,2,FALSE) -> ACCESSORIES | D28: =+VLOOKUP($B28,'CSM PRICE LIST 26.1.3'!$A$2:$E$110,3,FALSE) -> AHIR PERDESİ | E28: =+VLOOKUP($B28,'MASTER PRICE LIST'!$B$9:$K$117,4,FALSE) -> 99.9 | F28: =+VLOOKUP($B28,'MASTER PRICE LIST'!$B$9:$K$117,5,FALSE) -> 5490 | G28: =+F28*0.5 -> 2745 | H28: =+VLOOKUP($B28,'CSM PRICE LIST 26.1.3'!$A:$G,8,FALSE) -> #REF!
B29: PANDORA | C29: =+VLOOKUP($B29,'CSM PRICE LIST 26.1.3'!$A$2:$E$110,2,FALSE) -> HORSE | D29: =+VLOOKUP($B29,'CSM PRICE LIST 26.1.3'!$A$2:$E$110,3,FALSE) -> ÖRME KULAKLIK | E29: =+VLOOKUP($B29,'MASTER PRICE LIST'!$B$9:$K$117,4,FALSE) -> 39.9 | F29: =+VLOOKUP($B29,'MASTER PRICE LIST'!$B$9:$K$117,5,FALSE) -> 2190 | G29: =+F29*0.5 -> 1095 | H29: =+VLOOKUP($B29,'CSM PRICE LIST 26.1.3'!$A:$G,8,FALSE) -> #REF!
B30: PANDORA-P | C30: =+VLOOKUP($B30,'CSM PRICE LIST 26.1.3'!$A$2:$E$110,2,FALSE) -> HORSE | D30: =+VLOOKUP($B30,'CSM PRICE LIST 26.1.3'!$A$2:$E$110,3,FALSE) -> ÖRME PONY KULAKLIK | E30: =+VLOOKUP($B30,'MASTER PRICE LIST'!$B$9:$K$117,4,FALSE) -> 39.9 | F30: =+VLOOKUP($B30,'MASTER PRICE LIST'!$B$9:$K$117,5,FALSE) -> 2190 | G30: =+F30*0.5 -> 1095 | H30: =+VLOOKUP($B30,'CSM PRICE LIST 26.1.3'!$A:$G,8,FALSE) -> #REF!
B31: CAPPA | C31: =+VLOOKUP($B31,'CSM PRICE LIST 26.1.3'!$A$2:$E$110,2,FALSE) -> HORSE | D31: =+VLOOKUP($B31,'CSM PRICE LIST 26.1.3'!$A$2:$E$110,3,FALSE) -> TECH SERİSİ KULAKLIK | E31: =+VLOOKUP($B31,'MASTER PRICE LIST'!$B$9:$K$117,4,FALSE) -> 49.9 | F31: =+VLOOKUP($B31,'MASTER PRICE LIST'!$B$9:$K$117,5,FALSE) -> 2740 | G31: =+F31*0.5 -> 1370 | H31: =+VLOOKUP($B31,'CSM PRICE LIST 26.1.3'!$A:$G,8,FALSE) -> #REF!
B32: CAPPA-P | C32: =+VLOOKUP($B32,'CSM PRICE LIST 26.1.3'!$A$2:$E$110,2,FALSE) -> HORSE | D32: =+VLOOKUP($B32,'CSM PRICE LIST 26.1.3'!$A$2:$E$110,3,FALSE) -> TECH SERİSİ PONY KULAKLIK | E32: =+VLOOKUP($B32,'MASTER PRICE LIST'!$B$9:$K$117,4,FALSE) -> 49.9 | F32: =+VLOOKUP($B32,'MASTER PRICE LIST'!$B$9:$K$117,5,FALSE) -> 2740 | G32: =+F32*0.5 -> 1370 | H32: =+VLOOKUP($B32,'CSM PRICE LIST 26.1.3'!$A:$G,8,FALSE) -> #REF!
B33: FLEECE-X | C33: =+VLOOKUP($B33,'CSM PRICE LIST 26.1.3'!$A$2:$E$110,2,FALSE) -> HORSE | D33: =+VLOOKUP($B33,'CSM PRICE LIST 26.1.3'!$A$2:$E$110,3,FALSE) -> POLAR ÇALIŞMA BLANKETİ | E33: =+VLOOKUP($B33,'MASTER PRICE LIST'!$B$9:$K$117,4,FALSE) -> 79.9 | F33: =+VLOOKUP($B33,'MASTER PRICE LIST'!$B$9:$K$117,5,FALSE) -> 4390 | G33: =+F33*0.5 -> 2195 | H33: =+VLOOKUP($B33,'CSM PRICE LIST 26.1.3'!$A:$G,8,FALSE) -> #REF!
B34: FLEECE-XP | C34: =+VLOOKUP($B34,'CSM PRICE LIST 26.1.3'!$A$2:$E$110,2,FALSE) -> HORSE | D34: =+VLOOKUP($B34,'CSM PRICE LIST 26.1.3'!$A$2:$E$110,3,FALSE) -> PONY POLAR ÇALIŞMA BLANKETİ | E34: =+VLOOKUP($B34,'MASTER PRICE LIST'!$B$9:$K$117,4,FALSE) -> 79.9 | F34: =+VLOOKUP($B34,'MASTER PRICE LIST'!$B$9:$K$117,5,FALSE) -> 4390 | G34: =+F34*0.5 -> 2195 | H34: =+VLOOKUP($B34,'CSM PRICE LIST 26.1.3'!$A:$G,8,FALSE) -> #REF!
B35: LONDON | C35: =+VLOOKUP($B35,'CSM PRICE LIST 26.1.3'!$A$2:$E$110,2,FALSE) -> HORSE | D35: =+VLOOKUP($B35,'CSM PRICE LIST 26.1.3'!$A$2:$E$110,3,FALSE) -> ELMAS DESEN EYER ALTI | E35: =+VLOOKUP($B35,'MASTER PRICE LIST'!$B$9:$K$117,4,FALSE) -> 79.9 | F35: =+VLOOKUP($B35,'MASTER PRICE LIST'!$B$9:$K$117,5,FALSE) -> 4390 | G35: =+F35*0.5 -> 2195 | H35: =+VLOOKUP($B35,'CSM PRICE LIST 26.1.3'!$A:$G,8,FALSE) -> #REF!
B36: LONDON-P | C36: =+VLOOKUP($B36,'CSM PRICE LIST 26.1.3'!$A$2:$E$110,2,FALSE) -> HORSE | D36: =+VLOOKUP($B36,'CSM PRICE LIST 26.1.3'!$A$2:$E$110,3,FALSE) -> ELMAS DESEN PONY EYER ALTI | E36: =+VLOOKUP($B36,'MASTER PRICE LIST'!$B$9:$K$117,4,FALSE) -> 79.9 | F36: =+VLOOKUP($B36,'MASTER PRICE LIST'!$B$9:$K$117,5,FALSE) -> 4390 | G36: =+F36*0.5 -> 2195 | H36: =+VLOOKUP($B36,'CSM PRICE LIST 26.1.3'!$A:$G,8,FALSE) -> #REF!
B37: PARIS | C37: =+VLOOKUP($B37,'CSM PRICE LIST 26.1.3'!$A$2:$E$110,2,FALSE) -> HORSE | D37: =+VLOOKUP($B37,'CSM PRICE LIST 26.1.3'!$A$2:$E$110,3,FALSE) -> PETEK DESEN EYER ALTI | E37: =+VLOOKUP($B37,'MASTER PRICE LIST'!$B$9:$K$117,4,FALSE) -> 79.9 | F37: =+VLOOKUP($B37,'MASTER PRICE LIST'!$B$9:$K$117,5,FALSE) -> 4390 | G37: =+F37*0.5 -> 2195 | H37: =+VLOOKUP($B37,'CSM PRICE LIST 26.1.3'!$A:$G,8,FALSE) -> #REF!
... B81: ASPEN | C81: =+VLOOKUP($B81,'CSM PRICE LIST 26.1.3'!$A$2:$E$110,2,FALSE) -> RIDER | D81: =+VLOOKUP($B81,'CSM PRICE LIST 26.1.3'!$A$2:$E$110,3,FALSE) -> KADIN UZUN KOL FERMUARLI T-SHIRT | E81: =+VLOOKUP($B81,'MASTER PRICE LIST'!$B$9:$K$117,4,FALSE) -> 99.9 | F81: =+VLOOKUP($B81,'MASTER PRICE LIST'!$B$9:$K$117,5,FALSE) -> 5490 | G81: =+F81*0.5 -> 2745 | H81: =+VLOOKUP($B81,'CSM PRICE LIST 26.1.3'!$A:$G,8,FALSE) -> #REF!
B82: ASPEN-STRASS | C82: =+VLOOKUP($B82,'CSM PRICE LIST 26.1.3'!$A$2:$E$110,2,FALSE) -> RIDER | D82: =+VLOOKUP($B82,'CSM PRICE LIST 26.1.3'!$A$2:$E$110,3,FALSE) -> STRASS TAŞ DETAYLI KADIN UZUN KOL FERMUARLI T-SHIRT | E82: =+VLOOKUP($B82,'MASTER PRICE LIST'!$B$9:$K$117,4,FALSE) -> 119.9 | F82: =+VLOOKUP($B82,'MASTER PRICE LIST'!$B$9:$K$117,5,FALSE) -> 6590 | G82: =+F82*0.5 -> 3295
B83: ATLANTA | C83: =+VLOOKUP($B83,'CSM PRICE LIST 26.1.3'!$A$2:$E$110,2,FALSE) -> RIDER | D83: =+VLOOKUP($B83,'CSM PRICE LIST 26.1.3'!$A$2:$E$110,3,FALSE) -> ERKEK ŞİŞME YELEK | E83: =+VLOOKUP($B83,'MASTER PRICE LIST'!$B$9:$K$117,4,FALSE) -> 99.9 | F83: =+VLOOKUP($B83,'MASTER PRICE LIST'!$B$9:$K$117,5,FALSE) -> 5490 | G83: =+F83*0.5 -> 2745 | H83: =+VLOOKUP($B83,'CSM PRICE LIST 26.1.3'!$A:$G,8,FALSE) -> #REF!
B84: CANADA | C84: =+VLOOKUP($B84,'CSM PRICE LIST 26.1.3'!$A$2:$E$110,2,FALSE) -> RIDER | D84: =+VLOOKUP($B84,'CSM PRICE LIST 26.1.3'!$A$2:$E$110,3,FALSE) -> KADIN ŞİŞME YELEK | E84: =+VLOOKUP($B84,'MASTER PRICE LIST'!$B$9:$K$117,4,FALSE) -> 99.9 | F84: =+VLOOKUP($B84,'MASTER PRICE LIST'!$B$9:$K$117,5,FALSE) -> 5490 | G84: =+F84*0.5 -> 2745 | H84: =+VLOOKUP($B84,'CSM PRICE LIST 26.1.3'!$A:$G,8,FALSE) -> #REF!
B85: CHICAGO | C85: =+VLOOKUP($B85,'CSM PRICE LIST 26.1.3'!$A$2:$E$110,2,FALSE) -> RIDER | D85: =+VLOOKUP($B85,'CSM PRICE LIST 26.1.3'!$A$2:$E$110,3,FALSE) -> ERKEK POLAR HIRKA | E85: =+VLOOKUP($B85,'MASTER PRICE LIST'!$B$9:$K$117,4,FALSE) -> 99.9 | F85: =+VLOOKUP($B85,'MASTER PRICE LIST'!$B$9:$K$117,5,FALSE) -> 5490 | G85: =+F85*0.5 -> 2745 | H85: =+VLOOKUP($B85,'CSM PRICE LIST 26.1.3'!$A:$G,8,FALSE) -> #REF!
B86: COPENHAGEN | C86: =+VLOOKUP($B86,'CSM PRICE LIST 26.1.3'!$A$2:$E$110,2,FALSE) -> RIDER | D86: =+VLOOKUP($B86,'CSM PRICE LIST 26.1.3'!$A$2:$E$110,3,FALSE) -> ERKEK UZUN KOL T-SHIRT | E86: =+VLOOKUP($B86,'MASTER PRICE LIST'!$B$9:$K$117,4,FALSE) -> 99.9 | F86: =+VLOOKUP($B86,'MASTER PRICE LIST'!$B$9:$K$117,5,FALSE) -> 5490 | G86: =+F86*0.5 -> 2745 | H86: =+VLOOKUP($B86,'CSM PRICE LIST 26.1.3'!$A:$G,8,FALSE) -> #REF!
B87: ENZA-TBF | C87: =+VLOOKUP($B87,'CSM PRICE LIST 26.1.3'!$A$2:$E$110,2,FALSE) -> RIDER | D87: =+VLOOKUP($B87,'CSM PRICE LIST 26.1.3'!$A$2:$E$110,3,FALSE) -> KADIN KISA KOL YARIŞMA POLO X TEAM TÜRKİYE | E87: =+VLOOKUP($B87,'MASTER PRICE LIST'!$B$9:$K$117,4,FALSE) -> 99.9 | F87: =+VLOOKUP($B87,'MASTER PRICE LIST'!$B$9:$K$117,5,FALSE) -> 5490 | G87: =+F87*0.5 -> 2745 | H87: =+VLOOKUP($B87,'CSM PRICE LIST 26.1.3'!$A:$G,8,FALSE) -> #REF!
B88: ENZO-TBF | C88: =+VLOOKUP($B88,'CSM PRICE LIST 26.1.3'!$A$2:$E$110,2,FALSE) -> RIDER | D88: =+VLOOKUP($B88,'CSM PRICE LIST 26.1.3'!$A$2:$E$110,3,FALSE) -> ERKEK KISA KOL YARIŞMA POLO X TEAM TÜRKİYE | E88: =+VLOOKUP($B88,'MASTER PRICE LIST'!$B$9:$K$117,4,FALSE) -> 99.9 | F88: =+VLOOKUP($B88,'MASTER PRICE LIST'!$B$9:$K$117,5,FALSE) -> 5490 | G88: =+F88*0.5 -> 2745 | H88: =+VLOOKUP($B88,'CSM PRICE LIST 26.1.3'!$A:$G,8,FALSE) -> #REF!
B89: HELSINKI | C89: =+VLOOKUP($B89,'CSM PRICE LIST 26.1.3'!$A$2:$E$110,2,FALSE) -> RIDER | D89: =+VLOOKUP($B89,'CSM PRICE LIST 26.1.3'!$A$2:$E$110,3,FALSE) -> ERKEK UZUN KOL FERMUARLI T-SHIRT | E89: =+VLOOKUP($B89,'MASTER PRICE LIST'!$B$9:$K$117,4,FALSE) -> 99.9 | F89: =+VLOOKUP($B89,'MASTER PRICE LIST'!$B$9:$K$117,5,FALSE) -> 5490 | G89: =+F89*0.5 -> 2745 | H89: =+VLOOKUP($B89,'CSM PRICE LIST 26.1.3'!$A:$G,8,FALSE) -> #REF!
...
