Workbook
Name ATTRIBUTES: 'MASTER CODE DATA'!$S$2:$S$43
Name COLORLIST: 'MASTER CODE DATA'!$Q$2:$Q$999
Name DOLARKUR: #REF!
Name EURKUR: 'CSM ACTIVE PRICE LIST'!$E$1
Name MAINCATEGORY: 'MASTER CODE DATA'!$A$2:$A$99
Name MAINFABRIC: 'MASTER CODE DATA'!$O$2:$O$99
Name parite: 'CSM ACTIVE PRICE LIST'!$F$1
Name PRODUCTCATEGORY: 'MASTER CODE DATA'!$I$2:$I$99
Name PRODUCTGROUP: 'MASTER CODE DATA'!$E$2:$E$99
Name SEASON: 'MASTER CODE DATA'!$N$2:$N$99
Name SIZETYPES: 'MASTER CODE DATA'!$K$2:$K$99
Name STYLENAMES: 'STYLE NAMES'!$B$2:$B$520
Name TYPEGENDER: 'MASTER CODE DATA'!$G$2:$G$99
Name WEBCATEGORY: 'MASTER CODE DATA'!$C$2:$C$99
Name YEAR: 'MASTER CODE DATA'!$M$2:$M$99

Sheet NOTES & HOW TO USE
A1: 21.06.25 UPDATE
A2: NOTES & HOW TO USE THE FILE
A4: YENİ BİR MODEL GELİŞTİRİLECEĞİ ZAMAN (RENK YA DA VARYANT DEĞİL, YENİ BİR MODEL!) ÖNCE STYLE NAMES PAGE DEN BİR İSİM SEÇİLEREK KISA ÜRÜN TANIMI YAPILMALIDIR.
A6: SONRA CODE GENERATOR SAYFASINA YAPILACAK RENK VARYANTLARI İLE BERABER, YENİ, SIRADAKİ ARDIŞIK BİR ARTİKEL NUMARASI VERİLEREK, MANUEL OLARAK SATIR SATIR EKLENEREK KOD TANIMLAMALARI SEÇİLEREK YAPILMALIDIR
A8: DAHA ÖNCE YAPILMIŞ BİR MODELE RENK EKLENECEĞİ ZAMAN DA, CODE GENERATOR SAYFASINA MANUEL OLARAK EKLENMELİDİR. ART# NO SU DAHA ÖNCEKİ MODELE BAKILARAK VERİLMELİDİR
A10: HER YENİ KUMAŞ FABRIC TYPES SAYFASINA EKLENEREK KOD VERİLMELİ VE TAKİP EDİLMELİDİR
A14: ÖNEMLİ NOT:
A16: WEB SİTESİ FİYATLAMASI İÇİN STYLE CODES SAYFASINDA GÜNCEL FİYAT LİSTESİ EXCEL İNE LİNK VARDIR
A17: BU LİNK EURO VE TL GÜNCEL FİYATLARI ÇEKER
A18: İKİ DOSYANIN AYNI KLASÖR İÇERİSİNDE BULUNMADIĞI DURUMLARDA GÜNCEL FİYATLARI ÇEKEMEYEBİLİR
A19: BUNA DİKKAT EDEREK LİNK İN DOĞRU ÇALIŞTIĞINDAN EMİN OLMAK GEREKİR
A21: MASTER CODE DATA & TEMPLATE PAGE
... A134: HATALI GALİBA, ÇİFT VAR BU ÜRÜNLERDEN
A135: 8683711010487 | C135: CAPPA-F | D135: TECH EAR BONNET | E135: CAPPA-F / TJR0031BLKBLK
A136: 8683711010494 | C136: CAPPA-F | D136: TECH EAR BONNET | E136: CAPPA-F / TJR0031NAVNAV
A137: 8683711010500 | C137: CAPPA-P | D137: TECH EAR BONNET | E137: CAPPA-P / TJR0031BLKBLK
A138: 8683711010517 | C138: CAPPA-P | D138: TECH EAR BONNET | E138: CAPPA-P / TJR0031NAVNAV
A144: CODE GENSARI BOYALI FOTO NUMARALARINI KONTROL ET
A145: ESKİ FOTOLARIN SIZE LARINI KONTROL ET
A154: YENİ ÜRÜN AÇMA:
A155: ÖNCE STYLE NAMES SAYFASINDAN ÜRÜNE BİR İSİM VER VE YANDAKİ FORMÜL OLMAYAN KOLONLARA ÜRÜNÜN BİLGİLERİNİ GİR. FORMÜLLÜ KOLONLARI YUKARIDAKİ FORMÜLLERDEN KOPYALA
A156: CODE GENERATOR SAYFASINDA ÜRÜNÜN RENKLERİNİ AÇ, FOTOLARINI YAZ
A157: SKU LIST-LINKED SAYFASINA DA ÜRÜNÜN BEDENLERİNE GÖRE TEK TEK SATIR AÇ
A159: YAYINLAMAK İÇİN SKU LIST-LINKED SAYFASINI CSM SKU LIST EXCELİNDEKİ SKU LIST SAYFASINA DEĞER YAPIŞTIR DİYEREK KOPYALA
A160: DRIVE A CSM SKU LIST SAYFASINI KOYDUĞIUNDA REKLAM5 BURADAN OTOMATİK OKUYOR
A163: EŞ ZAMANLI OLARAK:
A164: ACTIVE PRICE LIST SAYFASINA ÜRÜNÜN FİYATINI GİR Kİ BURDAN FİYATI ÇEKSİN
A165: AMA BUNU ÖNCE MASTER PRICE LİST EXCELİNDE DÜZENLEYİP, ORADAKİ SAYFAYI FORMÜLLERİ BOZMADAN BU EXCELDEKİ ACTIVE PRICE LİST E KOPYALAMAN GEREK
A166: MODES AND SIZE INFO DA MODEL BİLGİLERİNİ GİRERSEN MODEL ADINA GÖRE FORMÜLLER ÇEKER
... A171: SKU LIST TEN BİR ÖRNEK
A172: BARCODE GS1/EAN | B172: ART. # | C172: STYLE NAME | D172: PRODUCT NAME | E172: PRODUCT CODE | F172: SIZE
A173: 8683711006855 | B173: 0066 | C173: LEONARDO | D173: MEN'S KNEE GRIP PRO BREECHES | E173: LEONARDO / TJR0026WHTWHT | F173: S / 44
A174: 8683711006862 | B174: 0066 | C174: LEONARDO | D174: MEN'S KNEE GRIP PRO BREECHES | E174: LEONARDO / TJR0026WHTWHT | F174: M / 46
A175: 8683711006879 | B175: 0066 | C175: LEONARDO | D175: MEN'S KNEE GRIP PRO BREECHES | E175: LEONARDO / TJR0026WHTWHT | F175: L / 48
A176: 8683711006886 | B176: 0066 | C176: LEONARDO | D176: MEN'S KNEE GRIP PRO BREECHES | E176: LEONARDO / TJR0026WHTWHT | F176: XL / 50
A177: 8683711006893 | B177: 0066 | C177: LEONARDO | D177: MEN'S KNEE GRIP PRO BREECHES | E177: LEONARDO / TJR0026WHTWHT | F177: XXL / 52
A179: NEDİM HER SIZE KIRLIMI İÇİN AYRI VERECEK | B179: BU SÜTUNLAR CODE GENERATOR DAN MANUEL KOPYALANACAK | F179: HER BEDEN İÇİN AYRI SATIR AÇILACAK

Sheet STYLE NAMES
A1: NAME CATEGORY | B1: STYLE NAMES | C1: PRODUCT NAME | D1: STYLE CATEGORY CODE | E1: MAIN CATEGORY | F1: WEB CATEGORY | G1: PRODUCT GROUP | H1: TYPE/GENDER | I1: PRODUCT CATEGORY | J1: ATTRIBUTES (OLD PROD. CAT) | K1: PRODUCT TITLE | L1: PRODUCT DESCRIPTION | M1: PRODUCT FEATURES | N1: CARE INSTRUCTIONS | O1: ÜRÜN ADI | P1: ÜRÜN AÇIKLAMASI | Q1: ÜRÜN ÖZELLİKLERİ | R1: YIKAMA TALİMATLARI | S1: NOME DEL PRODOTTO | T1: DESCRIZIONE DEL PRODOTTO | U1: CARATTERISTICHE DEL PRODOTTO | V1: ISTRUZIONI PER LA CURA | W1: PRODUKTNAME | X1: PRODUKTBESCHREIBUNG | Y1: PRODUKTMERKMALE | Z1: PFLEGEHINWEISE | AA1: € PRICE | AB1: TL PRICE | AC1: USD PRICE | AD1: SIZE TYPES | AE1: ATTRIBUTES (OLD PRODUCT CAT. KEY) | AF1: SIZE CHART REFERENCE | AG1: MAIN CATEGORY | AH1: WEB CATEGORY | AI1: PRODUCT GROUP | AJ1: TYPE/GENDER | AK1: PRODUCT CATEGORY
A2: 5-COMPETITION NAMES | B2: ABU DHABI | D2: =IF(C2>0,+AG2&"."&AI2&AJ2&"_"&AK2,"") | J2: 0 | K2: =IF(C2>0,C2,"") | AA2: =+IF($C2>0,VLOOKUP($B2,'CSM ACTIVE PRICE LIST'!$A$2:$F$1022,4,FALSE),"") | AB2: =+IF($C2>0,VLOOKUP($B2,'CSM ACTIVE PRICE LIST'!$A$2:$F$1022,5,FALSE),"") | AC2: =+IF($C2>0,VLOOKUP($B2,'CSM ACTIVE PRICE LIST'!$A$2:$F$1022,6,FALSE),"") | AE2: =+H2&J2 -> 0 | AG2: =IF($C2>0,+VLOOKUP(E2,'MASTER CODE DATA'!A$1:B$99,2,FALSE),"") | AH2: =IF(C2>0,+VLOOKUP(F2,'MASTER CODE DATA'!C$1:D$99,2,FALSE),"") | AI2: =IF(C2>0,+VLOOKUP(G2,'MASTER CODE DATA'!E$1:F$99,2,FALSE),"") | AJ2: =IF(C2>0,+VLOOKUP(H2,'MASTER CODE DATA'!G$1:H$99,2,FALSE),"") | AK2: =IF(C2>0,+VLOOKUP(I2,'MASTER CODE DATA'!I$1:J$99,2,FALSE),"")
A3: 7-KADIN İÇİN UYGUN İSİMLER | B3: ALABAMA | D3: =IF(C3>0,+AG3&"."&AI3&AJ3&"_"&AK3,"") | J3: 0 | K3: =IF(C3>0,C3,"") | AA3: =+IF($C3>0,VLOOKUP($B3,'CSM ACTIVE PRICE LIST'!$A$2:$F$1022,4,FALSE),"") | AB3: =+IF($C3>0,VLOOKUP($B3,'CSM ACTIVE PRICE LIST'!$A$2:$F$1022,5,FALSE),"") | AC3: =+IF($C3>0,VLOOKUP($B3,'CSM ACTIVE PRICE LIST'!$A$2:$F$1022,6,FALSE),"") | AE3: =+H3&J3 -> 0 | AG3: =IF($C3>0,+VLOOKUP(E3,'MASTER CODE DATA'!A$1:B$99,2,FALSE),"") | AH3: =IF(C3>0,+VLOOKUP(F3,'MASTER CODE DATA'!C$1:D$99,2,FALSE),"") | AI3: =IF(C3>0,+VLOOKUP(G3,'MASTER CODE DATA'!E$1:F$99,2,FALSE),"") | AJ3: =IF(C3>0,+VLOOKUP(H3,'MASTER CODE DATA'!G$1:H$99,2,FALSE),"") | AK3: =IF(C3>0,+VLOOKUP(I3,'MASTER CODE DATA'!I$1:J$99,2,FALSE),"")
A4: 2-WINTER NAMES | B4: ALASKA | C4: WINTER STABLE RUG | D4: =IF(C4>0,+AG4&"."&AI4&AJ4&"_"&AK4,"") -> H.RUGFL_STR | E4: HORSE | F4: HORSE | G4: RUGS | H4: FULL | I4: STABLE RUGS | J4: STABLE RUGS | K4: =IF(C4>0,C4,"") -> WINTER STABLE RUG | L4: Winter Stable Rug - 300 GR. Thanks to its quality and high-tech components, our winter rugs will keep your horse extra warm in the stable. Not to mention the elegant look! | M4: *Water-repellent heavy duty shell fabric *Soft, natural and skin-friendly lining fabric *300 gr Thermo Fiber Filling *Custom pattern to match your horses anatomy *Adjustable shoulder straps for better fitting and fleece collar *Non-breakable metal claps Composition: Shell fabric: 100% Polyester Lining: 100% Cotton Filling: 100% Polyester Non-woven | N4: Industrial washing is recommended | O4: KIŞLIK AHIR BLANKETİ | P4: Kışlık Ahır Blanketi - 300 GR Kaliteli ve yüksek teknik özellikli materyalleri ile Ahır Blanketlerimiz atınızı box içinde extra sıcak ve şık tutacak | Q4: *Su itici özellikli dayananıklı dış kumaş *Yumuşak, doğal ve cilt dostu astar kumaş *300 gr Termo Elyaf Dolgulu * Atınızın anatomisine uyacak özel kalıp * Atınızın üstüne daha iyi oturması için ayarlanabilir omuz kemerleri ve polar yaka *Kırılmaz metal tokalar Kompozisyon: Dış yüzey kumaşı: %100 Polyester Astar: %100 Pamuk Dolgu: %100 Polyester termo elyaf | R4: Endüstriyel yıkama tavsiye edilir | S4: COPERTA DA BOX INVERNALE | T4: Coperta invernale da box - 300 GR Grazie alla sua qualità e ai suoi componenti high-tech, le nostre coperte invernali manterranno il tuo cavallo extra caldo nella stalla con un elegante aspetto! | U4: *Tessuto esterno idroripellente e di alta qualità *Fodera interna morbida, naturale e delicata sulla pelle *300 gr di imbottitura in fibra termo-isolante *Design personalizzato per adattarsi all'anatomia del cavallo *Spalline regolabili per una migliore vestibilità e colletto in pile *Ganci in metallo infrangibile Composizione: Tessuto esterno: 100% Poliestere Fodera: 100% Cotone Imbottitura: 100% Poliestere | V4: Si consiglia il lavaggio industriale | AA4: =+IF($C4>0,VLOOKUP($B4,'CSM ACTIVE PRICE LIST'!$A$2:$F$1022,4,FALSE),"") -> 249.9 | AB4: =+IF($C4>0,VLOOKUP($B4,'CSM ACTIVE PRICE LIST'!$A$2:$F$1022,5,FALSE),"") -> 13740 | AC4: =+IF($C4>0,VLOOKUP($B4,'CSM ACTIVE PRICE LIST'!$A$2:$F$1022,6,FALSE),"") -> 287.385 | AD4: =+VLOOKUP(B4,'SKU LIST - LINKED'!C:W,21,FALSE) -> S;M;L;XL | AE4: =+H4&"-"&J4 -> FULL-STABLE RUGS | AF4: =+VLOOKUP(B4,'[1]STYLES & SIZE CHARTS'!$A:$H,8,FALSE) -> HP-RUGS1 | AG4: =IF($C4>0,+VLOOKUP(E4,'MASTER CODE DATA'!A$1:B$99,2,FALSE),"") -> H | AH4: =IF(C4>0,+VLOOKUP(F4,'MASTER CODE DATA'!C$1:D$99,2,FALSE),"") -> HRS | AI4: =IF(C4>0,+VLOOKUP(G4,'MASTER CODE DATA'!E$1:F$99,2,FALSE),"") -> RUG | AJ4: =IF(C4>0,+VLOOKUP(H4,'MASTER CODE DATA'!G$1:H$99,2,FALSE),"") -> FL | AK4: =IF(C4>0,+VLOOKUP(I4,'MASTER CODE DATA'!I$1:J$99,2,FALSE),"") -> STR
A5: 2-WINTER NAMES | B5: ALASKA-P | C5: WINTER STABLE RUG | D5: =IF(C5>0,+AG5&"."&AI5&AJ5&"_"&AK5,"") -> H.RUGPN_STR | E5: HORSE | F5: PONY | G5: RUGS | H5: PONY | I5: STABLE RUGS | J5: STABLE RUGS | K5: =IF(C5>0,H5&" - "&C5,"") -> PONY - WINTER STABLE RUG | L5: Pony Winter Stable Rug - 300 GR. Thanks to its quality and high-tech components, our winter rugs will keep your horse extra warm in the stable. Not to mention the elegant look! | M5: *Water-repellent heavy duty shell fabric *Soft, natural and skin-friendly lining fabric *300 gr Thermo Fiber Filling *Custom pattern to match your horses anatomy *Adjustable shoulder straps for better fitting and fleece collar *Non-breakable metal claps Composition: Shell fabric: 100% Polyester Lining: 100% Cotton Filling: 100% Polyester Non-woven | N5: Industrial washing is recommended | O5: PONY KIŞLIK AHIR BLANKETİ | P5: Pony Kışlık Ahır Blanketi - 300 GR Kaliteli ve yüksek teknik özellikli materyalleri ile Ahır Blanketlerimiz atınızı box içinde extra sıcak ve şık tutacak | Q5: *Su itici özellikli dayananıklı dış kumaş *Yumuşak, doğal ve cilt dostu astar kumaş *300 gr Termo Elyaf Dolgulu * Atınızın anatomisine uyacak özel kalıp * Atınızın üstüne daha iyi oturması için ayarlanabilir omuz kemerleri ve polar yaka *Kırılmaz metal tokalar Kompozisyon: Dış yüzey kumaşı: %100 Polyester Astar: %100 Pamuk Dolgu: %100 Polyester termo elyaf | R5: Endüstriyel yıkama tavsiye edilir | S5: COPERTA DA BOX INVERNALE X PONY | T5: Coperta invernale da box per Pony - 300 GR Grazie alla sua qualità e ai suoi componenti high-tech, le nostre coperte invernali manterranno il tuo cavallo extra caldo nella stalla con un elegante aspetto! | U5: *Tessuto esterno idroripellente e di alta qualità *Fodera interna morbida, naturale e delicata sulla pelle *300 gr di imbottitura in fibra termo-isolante *Design personalizzato per adattarsi all'anatomia del cavallo *Spalline regolabili per una migliore vestibilità e colletto in pile *Ganci in metallo infrangibile Composizione: Tessuto esterno: 100% Poliestere Fodera: 100% Cotone Imbottitura: 100% Poliestere | V5: Si consiglia il lavaggio industriale | AA5: =+IF($C5>0,VLOOKUP($B5,'CSM ACTIVE PRICE LIST'!$A$2:$F$1022,4,FALSE),"") -> 249.9 | AB5: =+IF($C5>0,VLOOKUP($B5,'CSM ACTIVE PRICE LIST'!$A$2:$F$1022,5,FALSE),"") -> 13740 | AC5: =+IF($C5>0,VLOOKUP($B5,'CSM ACTIVE PRICE LIST'!$A$2:$F$1022,6,FALSE),"") -> 287.385 | AD5: =+VLOOKUP(B5,'SKU LIST - LINKED'!C:W,21,FALSE) -> XXS;XS | AE5: =+H5&"-"&J5 -> PONY-STABLE RUGS | AF5: =+VLOOKUP(B5,'[1]STYLES & SIZE CHARTS'!$A:$H,8,FALSE) -> HP-RUGS1 | AG5: =IF($C5>0,+VLOOKUP(E5,'MASTER CODE DATA'!A$1:B$99,2,FALSE),"") -> H | AH5: =IF(C5>0,+VLOOKUP(F5,'MASTER CODE DATA'!C$1:D$99,2,FALSE),"") -> PNY | AI5: =IF(C5>0,+VLOOKUP(G5,'MASTER CODE DATA'!E$1:F$99,2,FALSE),"") -> RUG | AJ5: =IF(C5>0,+VLOOKUP(H5,'MASTER CODE DATA'!G$1:H$99,2,FALSE),"") -> PN | AK5: =IF(C5>0,+VLOOKUP(I5,'MASTER CODE DATA'!I$1:J$99,2,FALSE),"") -> STR
A6: 4-GENERAL USE NAMES | B6: ALBANIA | D6: =IF(C6>0,+AG6&"."&AI6&AJ6&"_"&AK6,"") | J6: 0 | K6: =IF(C6>0,C6,"") | AA6: =+IF($C6>0,VLOOKUP($B6,'CSM ACTIVE PRICE LIST'!$A$2:$F$1022,4,FALSE),"") | AB6: =+IF($C6>0,VLOOKUP($B6,'CSM ACTIVE PRICE LIST'!$A$2:$F$1022,5,FALSE),"") | AC6: =+IF($C6>0,VLOOKUP($B6,'CSM ACTIVE PRICE LIST'!$A$2:$F$1022,6,FALSE),"") | AE6: =+H6&J6 -> 0 | AG6: =IF($C6>0,+VLOOKUP(E6,'MASTER CODE DATA'!A$1:B$99,2,FALSE),"") | AH6: =IF(C6>0,+VLOOKUP(F6,'MASTER CODE DATA'!C$1:D$99,2,FALSE),"") | AI6: =IF(C6>0,+VLOOKUP(G6,'MASTER CODE DATA'!E$1:F$99,2,FALSE),"") | AJ6: =IF(C6>0,+VLOOKUP(H6,'MASTER CODE DATA'!G$1:H$99,2,FALSE),"") | AK6: =IF(C6>0,+VLOOKUP(I6,'MASTER CODE DATA'!I$1:J$99,2,FALSE),"")
A7: 2-WINTER NAMES | B7: ALBANY | D7: =IF(C7>0,+AG7&"."&AI7&AJ7&"_"&AK7,"") | J7: 0 | K7: =IF(C7>0,C7,"") | AA7: =+IF($C7>0,VLOOKUP($B7,'CSM ACTIVE PRICE LIST'!$A$2:$F$1022,4,FALSE),"") | AB7: =+IF($C7>0,VLOOKUP($B7,'CSM ACTIVE PRICE LIST'!$A$2:$F$1022,5,FALSE),"") | AC7: =+IF($C7>0,VLOOKUP($B7,'CSM ACTIVE PRICE LIST'!$A$2:$F$1022,6,FALSE),"") | AE7: =+H7&J7 -> 0 | AG7: =IF($C7>0,+VLOOKUP(E7,'MASTER CODE DATA'!A$1:B$99,2,FALSE),"") | AH7: =IF(C7>0,+VLOOKUP(F7,'MASTER CODE DATA'!C$1:D$99,2,FALSE),"") | AI7: =IF(C7>0,+VLOOKUP(G7,'MASTER CODE DATA'!E$1:F$99,2,FALSE),"") | AJ7: =IF(C7>0,+VLOOKUP(H7,'MASTER CODE DATA'!G$1:H$99,2,FALSE),"") | AK7: =IF(C7>0,+VLOOKUP(I7,'MASTER CODE DATA'!I$1:J$99,2,FALSE),"")
A8: 7-KADIN İÇİN UYGUN İSİMLER | B8: ALEA | C8: WOMEN'S KNEE GRIP PRO BREECHES | D8: =IF(C8>0,+AG8&"."&AI8&AJ8&"_"&AK8,"") -> R.BOTWN_BRC | E8: RIDER | F8: WOMEN | G8: BOTTOMS | H8: WOMEN | I8: BREECHES | J8: BREECHES | K8: =IF(C8>0,C8,"") -> WOMEN'S KNEE GRIP PRO BREECHES | L8: MADE IN ITALY WITH PREMIUM ITALIAN FABRICS Professional Series Breeches that comes in a very soft microfibre that fit snugly that allows full movement whatever your discipline. Ideal for a long day activity. Grip knees for the best comfort. Finished with an elastic sock for a perfect fit. | M8: *Italian Premium fabric *Extra-soft and comfortable technical jersey *4-way stretch fabric *Breathable and Quick Dry *Wrinkle-free and Easy Care *Knee Grip Composition: 74% Micro PA / 26% Elasthane | N8: Machine Wash at 30°C Mild process Iron at low temperature Iron from REVERSE Do NOT iron on logos or prints Do not bleach Do NOT Tumble Dry | O8: KADIN PRO BİNİCİ PANTOLONU | P8: EN İYİ KALİTE İTALYAN KUMAŞLAR İLE İTALYA'DA ÜRETİLMİŞTİR Profesyonel Seri Binici Pantolonu; oldukça yumuşak mikrofiber kumaştan üretilmiş olup, her branşta tam hareket özgürlüğü sağlayacak şekilde vücuda tam oturur. Yoğun geçen günlerde idealdir. En iyi konfor için dizde grip detayı. Mükemmel uyum için elastik çorapla tamamlanmıştır. | Q8: *İtalyan Premium kumaş *Ekstra yumuşak ve konforlu teknik jarse *4 yönlü esneme özelliği *Nefes alabilir ve hızlı kurur *Kırışmaz ve kolay bakım *Diz Grip Bileşimi: %74 Mikro PA / %26 Elastan | R8: Makinede 30°C' de Yıkayın Hassas Yıkama Ilık ütü yapın Tersten ütüleyin Logo ve baskıları ÜTÜLEMEYİN Çamaşır suyu kullanmayın Kurutma Makinesinde Kurutmayın | S8: PANTALONI KNEE GRIP PRO DA DONNA | T8: PRODOTTO IN ITALIA CON TESSUTI ITALIANI DI ALTA QUALITÀ Realizzato in microfibra Sensitive extra comfort idrorepellente e traspirante, accompagna i movimenti senza costrizioni ed è ideale per attività fisiche anche prolungate. Fondo elastico per garantire un’ottima calzata, grip applicato al ginocchio per la massima aderenza e comfort | U8: *Tessuto premium italiano *Jersey tecnico extra morbido e confortevole *Tessuto elasticizzato in 4 direzioni *Traspirante e ad asciugatura rapida *Antipiega e facile da curare *Knee Grip Composizione: 74% Micro PA / 26% Elastan | V8: Lavare in lavatrice a 30°C Ciclo delicato Stirare a bassa temperatura Stirare al rovescio Non stirare su loghi o stampe Non candeggiare Non asciugare in asciugatrice | AA8: =+IF($C8>0,VLOOKUP($B8,'CSM ACTIVE PRICE LIST'!$A$2:$F$1022,4,FALSE),"") -> 219.9 | AB8: =+IF($C8>0,VLOOKUP($B8,'CSM ACTIVE PRICE LIST'!$A$2:$F$1022,5,FALSE),"") -> 12090 | AC8: =+IF($C8>0,VLOOKUP($B8,'CSM ACTIVE PRICE LIST'!$A$2:$F$1022,6,FALSE),"") -> 252.885 | AD8: =+VLOOKUP(B8,'SKU LIST - LINKED'!C:W,21,FALSE) -> XXS / 32-34;XS / 34-36;S / 36-38;M / 38-40;L / 40-42;XL / 42-44 | AE8: =+H8&"-"&J8 -> WOMEN-BREECHES | AF8: =+VLOOKUP(B8,'[1]STYLES & SIZE CHARTS'!$A:$H,8,FALSE) -> WB-BR1 | AG8: =IF($C8>0,+VLOOKUP(E8,'MASTER CODE DATA'!A$1:B$99,2,FALSE),"") -> R | AH8: =IF(C8>0,+VLOOKUP(F8,'MASTER CODE DATA'!C$1:D$99,2,FALSE),"") -> WMN | AI8: =IF(C8>0,+VLOOKUP(G8,'MASTER CODE DATA'!E$1:F$99,2,FALSE),"") -> BOT | AJ8: =IF(C8>0,+VLOOKUP(H8,'MASTER CODE DATA'!G$1:H$99,2,FALSE),"") -> WN | AK8: =IF(C8>0,+VLOOKUP(I8,'MASTER CODE DATA'!I$1:J$99,2,FALSE),"") -> BRC
B9: ALEA-W | C9: WOMEN'S KNEE GRIP PRO WINTER BREECHES | D9: =IF(C9>0,+AG9&"."&AI9&AJ9&"_"&AK9,"") -> R.BOTWN_BRC | E9: RIDER | F9: WOMEN | G9: BOTTOMS | H9: WOMEN | I9: BREECHES | J9: BREECHES | K9: =IF(C9>0,C9,"") -> WOMEN'S KNEE GRIP PRO WINTER BREECHES | L9: MADE IN ITALY WITH PREMIUM ITALIAN FABRICS Professional Series Winter Breeches that comes in a very soft microfibre on the surface fabric and a heat tech polar fabric on the inside to keep you warm during cold weather conditions and provide full movement whatever your discipline. Ideal for a long day activity. Grip knees for the best comfort. Finished with an elastic sock for a perfect fit. | M9: *Italian Premium fabric *Extra-soft and comfortable technical jersey with heat tech polar fabric inside *4-way stretch fabric *Breathable and Quick Dry *Wrinkle-free and Easy Care *Knee Grip Composition: 74% Micro PA / 26% Elasthane | N9: Machine Wash at 30°C Mild process Iron at low temperature Iron from REVERSE Do NOT iron on logos or prints Do not bleach Do NOT Tumble Dry | O9: KIŞLIK KADIN PRO BİNİCİ PANTOLONU | P9: EN İYİ KALİTE İTALYAN KUMAŞLAR İLE İTALYA'DA ÜRETİLMİŞTİR Profesyonel Seri Kışlık Binici Pantolonu; yüzeyde dört yöne esneyen yumuşak mikrofiber kumaştan ve iç kısmında ısı tutan polar kumaş ile üretilmiş olup, her branşta tam hareket özgürlüğü sağlayacak şekilde vücuda tam oturur. Soğuk hava şartlarında kullanmak için idealdir. En iyi konfor için dizde grip detayı. Mükemmel uyum için elastik çorapla tamamlanmıştır. | Q9: *İtalyan Premium kumaş *Dışı ekstra yumuşak ve konforlu teknik jarse, içi ısı tutan polar kumaş *4 yönlü esneme özelliği *Nefes alabilir ve hızlı kurur *Kırışmaz ve kolay bakım *Diz Grip Bileşimi: %74 Mikro PA / %26 Elastan | R9: Makinede 30°C' de Yıkayın Hassas Yıkama Ilık ütü yapın Tersten ütüleyin Logo ve baskıları ÜTÜLEMEYİN Çamaşır suyu kullanmayın Kurutma Makinesinde Kurutmayın | S9: PANTALONI INVERNALI KNEE GRIP PRO DA DONNA | T9: PRODOTTO IN ITALIA CON TESSUTI ITALIANI DI ALTA QUALITÀ Realizzato in faccia con tessuto microfibra Sensitive extra comfort idrorepellente e traspirante, e dentro con felpa heat tech per tenervi caldo nei ambienti molto freddi. Ideale per attività fisiche anche prolungate. Fondo elastico per garantire un’ottima calzata, grip applicato al ginocchio per la massima aderenza e comfort | U9: *Tessuto premium italiano *Jersey tecnico extra morbido e confortevole con felpa heat tech dentro *Tessuto elasticizzato in 4 direzioni *Traspirante e ad asciugatura rapida *Antipiega e facile da curare *Knee Grip Composizione: 74% Micro PA / 26% Elastan | V9: Lavare in lavatrice a 30°C Ciclo delicato Stirare a bassa temperatura Stirare al rovescio Non stirare su loghi o stampe Non candeggiare Non asciugare in asciugatrice | AA9: =+IF($C9>0,VLOOKUP($B9,'CSM ACTIVE PRICE LIST'!$A$2:$F$1022,4,FALSE),"") -> 229.9 | AB9: =+IF($C9>0,VLOOKUP($B9,'CSM ACTIVE PRICE LIST'!$A$2:$F$1022,5,FALSE),"") -> 12640 | AC9: =+IF($C9>0,VLOOKUP($B9,'CSM ACTIVE PRICE LIST'!$A$2:$F$1022,6,FALSE),"") -> 264.385 | AD9: =+VLOOKUP(B9,'SKU LIST - LINKED'!C:W,21,FALSE) -> XXS / 32-34;XS / 34-36;S / 36-38;M / 38-40;L / 40-42;XL / 42-44 | AE9: =+H9&"-"&J9 -> WOMEN-BREECHES | AF9: =+VLOOKUP(B9,'[1]STYLES & SIZE CHARTS'!$A:$H,8,FALSE) -> WB-BR1 | AG9: =IF($C9>0,+VLOOKUP(E9,'MASTER CODE DATA'!A$1:B$99,2,FALSE),"") -> R | AH9: =IF(C9>0,+VLOOKUP(F9,'MASTER CODE DATA'!C$1:D$99,2,FALSE),"") -> WMN | AI9: =IF(C9>0,+VLOOKUP(G9,'MASTER CODE DATA'!E$1:F$99,2,FALSE),"") -> BOT | AJ9: =IF(C9>0,+VLOOKUP(H9,'MASTER CODE DATA'!G$1:H$99,2,FALSE),"") -> WN | AK9: =IF(C9>0,+VLOOKUP(I9,'MASTER CODE DATA'!I$1:J$99,2,FALSE),"") -> BRC
A10: 4-GENERAL USE NAMES | B10: ALEX | C10: KID'S FLEECE JUMPER | D10: =IF(C10>0,+AG10&"."&AI10&AJ10&"_"&AK10,"") -> R.S&JKU_JMP | E10: RIDER | F10: JUNIOR | G10: SWEATS & JUMPERS | H10: KIDS UNISEX | I10: JUMPERS | J10: JUMPERS | K10: =IF(C10>0,C10,"") -> KID'S FLEECE JUMPER | L10: CSM fleece jumpers are made with high quality fleece fabric to keep you warm in the horse world where you spend the majority of your time in the outdoors. | M10: *High density & soft fleece fabric *Extra-warm Composition: 100% Polyester | N10: Machine Wash at 30°C Mild process Do not bleach Do NOT Tumble Dry | O10: ÇOCUK POLAR HIRKA | P10: CSM polar hırkalar zamanınızın çoğunu açık havada geçirdiğiniz at dünyasında sizi sıcak tutmak için yüksek kaliteli polar kumaştan üretilmiştir. | Q10: * Yüksek denye & yumuşak polar kumaş * Extra sıcak tutma Kompozisyon: 100% Polyester | R10: Makinede 30°C' de Yıkayın Hassas Yıkama Çamaşır suyu kullanmayın Kurutma Makinesinde Kurutmayın | S10: FELPA DI PILE DA JUNIOR | T10: Felpe in pile CSM Realizzate con tessuto in pile di alta qualità per tenerti al caldo nel mondo dell'equitazione, dove trascorri la maggior parte del tuo tempo all'aperto. | U10: Tessuto in pile ad alta densità e morbidezza Extra caldo Composizione: 100% Poliestere | V10: Lavare in lavatrice a 30°C Ciclo delicato Non candeggiare Non asciugare in asciugatrice | AA10: =+IF($C10>0,VLOOKUP($B10,'CSM ACTIVE PRICE LIST'!$A$2:$F$1022,4,FALSE),"") -> 99.9 | AB10: =+IF($C10>0,VLOOKUP($B10,'CSM ACTIVE PRICE LIST'!$A$2:$F$1022,5,FALSE),"") -> 5490 | AC10: =+IF($C10>0,VLOOKUP($B10,'CSM ACTIVE PRICE LIST'!$A$2:$F$1022,6,FALSE),"") -> 114.885 | AD10: =+VLOOKUP(B10,'SKU LIST - LINKED'!C:W,21,FALSE) -> #N/A | AE10: =+H10&"-"&J10 -> KIDS UNISEX-JUMPERS | AF10: =+VLOOKUP(B10,'[1]STYLES & SIZE CHARTS'!$A:$H,8,FALSE) -> 0 | AG10: =IF($C10>0,+VLOOKUP(E10,'MASTER CODE DATA'!A$1:B$99,2,FALSE),"") -> R | AH10: =IF(C10>0,+VLOOKUP(F10,'MASTER CODE DATA'!C$1:D$99,2,FALSE),"") -> JNR | AI10: =IF(C10>0,+VLOOKUP(G10,'MASTER CODE DATA'!E$1:F$99,2,FALSE),"") -> S&J | AJ10: =IF(C10>0,+VLOOKUP(H10,'MASTER CODE DATA'!G$1:H$99,2,FALSE),"") -> KU | AK10: =IF(C10>0,+VLOOKUP(I10,'MASTER CODE DATA'!I$1:J$99,2,FALSE),"") -> JMP
A11: 7-KADIN İÇİN UYGUN İSİMLER | B11: ALLEGRA | C11: WOMEN'S FULL GRIP PRO LEGGINGS | D11: =IF(C11>0,+AG11&"."&AI11&AJ11&"_"&AK11,"") -> R.BOTWN_LGN | E11: RIDER | F11: WOMEN | G11: BOTTOMS | H11: WOMEN | I11: LEGGINGS | J11: LEGGINGS | K11: =IF(C11>0,C11,"") -> WOMEN'S FULL GRIP PRO LEGGINGS | L11: MADE IN ITALY WITH PREMIUM ITALIAN FABRICS Professional leggings in lurex microfibre, perfect wearability for all day activities. Side pockets and full grip applied for the best comfort. | M11: *Italian Premium fabric *Extra-soft and comfortable technical jersey *4-way stretch fabric *Breathable and Quick Dry *Wrinkle-free and Easy Care *Full Grip Composition: 74% Micro PA / 26% Elasthane | N11: Machine Wash at 30°C Mild process Iron at low temperature Iron from REVERSE Do NOT iron on logos or prints Do not bleach Do NOT Tumble Dry | O11: KADIN FULL GRIP PRO BİNİCİ TAYTI | P11: EN İYİ KALİTE İTALYAN KUMAŞLAR İLE İTALYA'DA ÜRETİLMİŞTİR Dört yöne esneyen mikrofiberden profesyonel tayt, tüm gün aktivitelerinde mükemmel giyilebilirlik sunar. En iyi konfor için yan cepler ve full grip detayları uygulanmıştır. | Q11: *İtalyan Premium kumaş *Ekstra yumuşak ve konforlu teknik jarse *4 yönlü esneme özelliği *Nefes alabilir ve hızlı kurur *Kırışmaz ve kolay bakım *Full Grip Bileşimi: %72 Mikro PA / %28 Elastan | R11: Makinede 30°C' de Yıkayın Hassas Yıkama Ilık ütü yapın Tersten ütüleyin Logo ve baskıları ÜTÜLEMEYİN Çamaşır suyu kullanmayın Kurutma Makinesinde Kurutmayın | S11: LEGGINGS FULL GRIP PRO DA DONNA | T11: PRODOTTO IN ITALIA CON TESSUTI ITALIANI DI ALTA QUALITÀ Leggings realizzato in microfibra super elastico che garantisce perfetta vestibilità e durabilità nel tempo. Tasche al fianco e full grip applicato per il massimo comfort | U11: *Tessuto premium italiano *Jersey tecnico extra morbido e confortevole *Tessuto elasticizzato in 4 direzioni *Traspirante e ad asciugatura rapida *Antipiega e facile da curare *Full Grip Composizione: 74% Micro PA / 26% Elastan | V11: Lavare in lavatrice a 30°C Ciclo delicato Stirare a bassa temperatura Stirare al rovescio Non stirare su loghi o stampe Non candeggiare Non asciugare in asciugatrice | AA11: =+IF($C11>0,VLOOKUP($B11,'CSM ACTIVE PRICE LIST'!$A$2:$F$1022,4,FALSE),"") -> 109.9 | AB11: =+IF($C11>0,VLOOKUP($B11,'CSM ACTIVE PRICE LIST'!$A$2:$F$1022,5,FALSE),"") -> 6040 | AC11: =+IF($C11>0,VLOOKUP($B11,'CSM ACTIVE PRICE LIST'!$A$2:$F$1022,6,FALSE),"") -> 126.385 | AD11: =+VLOOKUP(B11,'SKU LIST - LINKED'!C:W,21,FALSE) -> XS / 34-36;S / 36-38;M / 38-40;L / 40-42;XL / 42-44 | AE11: =+H11&"-"&J11 -> WOMEN-LEGGINGS | AF11: =+VLOOKUP(B11,'[1]STYLES & SIZE CHARTS'!$A:$H,8,FALSE) -> WB-L1 | AG11: =IF($C11>0,+VLOOKUP(E11,'MASTER CODE DATA'!A$1:B$99,2,FALSE),"") -> R | AH11: =IF(C11>0,+VLOOKUP(F11,'MASTER CODE DATA'!C$1:D$99,2,FALSE),"") -> WMN | AI11: =IF(C11>0,+VLOOKUP(G11,'MASTER CODE DATA'!E$1:F$99,2,FALSE),"") -> BOT | AJ11: =IF(C11>0,+VLOOKUP(H11,'MASTER CODE DATA'!G$1:H$99,2,FALSE),"") -> WN | AK11: =IF(C11>0,+VLOOKUP(I11,'MASTER CODE DATA'!I$1:J$99,2,FALSE),"") -> LGN
A12: 7-KADIN İÇİN UYGUN İSİMLER | B12: ALMEIRA | D12: =IF(C12>0,+AG12&"."&AI12&AJ12&"_"&AK12,"") | J12: 0 | K12: =IF(C12>0,C12,"") | AA12: =+IF($C12>0,VLOOKUP($B12,'CSM ACTIVE PRICE LIST'!$A$2:$F$1022,4,FALSE),"") | AB12: =+IF($C12>0,VLOOKUP($B12,'CSM ACTIVE PRICE LIST'!$A$2:$F$1022,5,FALSE),"") | AC12: =+IF($C12>0,VLOOKUP($B12,'CSM ACTIVE PRICE LIST'!$A$2:$F$1022,6,FALSE),"") | AE12: =+H12&J12 -> 0 | AG12: =IF($C12>0,+VLOOKUP(E12,'MASTER CODE DATA'!A$1:B$99,2,FALSE),"") | AH12: =IF(C12>0,+VLOOKUP(F12,'MASTER CODE DATA'!C$1:D$99,2,FALSE),"") | AI12: =IF(C12>0,+VLOOKUP(G12,'MASTER CODE DATA'!E$1:F$99,2,FALSE),"") | AJ12: =IF(C12>0,+VLOOKUP(H12,'MASTER CODE DATA'!G$1:H$99,2,FALSE),"") | AK12: =IF(C12>0,+VLOOKUP(I12,'MASTER CODE DATA'!I$1:J$99,2,FALSE),"")
A13: 5-COMPETITION NAMES | B13: AMALFI | D13: =IF(C13>0,+AG13&"."&AI13&AJ13&"_"&AK13,"") | J13: 0 | K13: =IF(C13>0,C13,"") | AA13: =+IF($C13>0,VLOOKUP($B13,'CSM ACTIVE PRICE LIST'!$A$2:$F$1022,4,FALSE),"") | AB13: =+IF($C13>0,VLOOKUP($B13,'CSM ACTIVE PRICE LIST'!$A$2:$F$1022,5,FALSE),"") | AC13: =+IF($C13>0,VLOOKUP($B13,'CSM ACTIVE PRICE LIST'!$A$2:$F$1022,6,FALSE),"") | AE13: =+H13&J13 -> 0 | AG13: =IF($C13>0,+VLOOKUP(E13,'MASTER CODE DATA'!A$1:B$99,2,FALSE),"") | AH13: =IF(C13>0,+VLOOKUP(F13,'MASTER CODE DATA'!C$1:D$99,2,FALSE),"") | AI13: =IF(C13>0,+VLOOKUP(G13,'MASTER CODE DATA'!E$1:F$99,2,FALSE),"") | AJ13: =IF(C13>0,+VLOOKUP(H13,'MASTER CODE DATA'!G$1:H$99,2,FALSE),"") | AK13: =IF(C13>0,+VLOOKUP(I13,'MASTER CODE DATA'!I$1:J$99,2,FALSE),"")
A14: 1-TOP NAMES | B14: AMSTERDAM | D14: =IF(C14>0,+AG14&"."&AI14&AJ14&"_"&AK14,"") | J14: 0 | K14: =IF(C14>0,C14,"") | AA14: =+IF($C14>0,VLOOKUP($B14,'CSM ACTIVE PRICE LIST'!$A$2:$F$1022,4,FALSE),"") | AB14: =+IF($C14>0,VLOOKUP($B14,'CSM ACTIVE PRICE LIST'!$A$2:$F$1022,5,FALSE),"") | AC14: =+IF($C14>0,VLOOKUP($B14,'CSM ACTIVE PRICE LIST'!$A$2:$F$1022,6,FALSE),"") | AE14: =+H14&J14 -> 0 | AG14: =IF($C14>0,+VLOOKUP(E14,'MASTER CODE DATA'!A$1:B$99,2,FALSE),"") | AH14: =IF(C14>0,+VLOOKUP(F14,'MASTER CODE DATA'!C$1:D$99,2,FALSE),"") | AI14: =IF(C14>0,+VLOOKUP(G14,'MASTER CODE DATA'!E$1:F$99,2,FALSE),"") | AJ14: =IF(C14>0,+VLOOKUP(H14,'MASTER CODE DATA'!G$1:H$99,2,FALSE),"") | AK14: =IF(C14>0,+VLOOKUP(I14,'MASTER CODE DATA'!I$1:J$99,2,FALSE),"")
A15: 5-COMPETITION NAMES | B15: ANCONA | D15: =IF(C15>0,+AG15&"."&AI15&AJ15&"_"&AK15,"") | J15: 0 | K15: =IF(C15>0,C15,"") | AA15: =+IF($C15>0,VLOOKUP($B15,'CSM ACTIVE PRICE LIST'!$A$2:$F$1022,4,FALSE),"") | AB15: =+IF($C15>0,VLOOKUP($B15,'CSM ACTIVE PRICE LIST'!$A$2:$F$1022,5,FALSE),"") | AC15: =+IF($C15>0,VLOOKUP($B15,'CSM ACTIVE PRICE LIST'!$A$2:$F$1022,6,FALSE),"") | AE15: =+H15&J15 -> 0 | AG15: =IF($C15>0,+VLOOKUP(E15,'MASTER CODE DATA'!A$1:B$99,2,FALSE),"") | AH15: =IF(C15>0,+VLOOKUP(F15,'MASTER CODE DATA'!C$1:D$99,2,FALSE),"") | AI15: =IF(C15>0,+VLOOKUP(G15,'MASTER CODE DATA'!E$1:F$99,2,FALSE),"") | AJ15: =IF(C15>0,+VLOOKUP(H15,'MASTER CODE DATA'!G$1:H$99,2,FALSE),"") | AK15: =IF(C15>0,+VLOOKUP(I15,'MASTER CODE DATA'!I$1:J$99,2,FALSE),"")
A16: 5-COMPETITION NAMES | B16: ANDORRA | D16: =IF(C16>0,+AG16&"."&AI16&AJ16&"_"&AK16,"") | J16: 0 | K16: =IF(C16>0,C16,"") | AA16: =+IF($C16>0,VLOOKUP($B16,'CSM ACTIVE PRICE LIST'!$A$2:$F$1022,4,FALSE),"") | AB16: =+IF($C16>0,VLOOKUP($B16,'CSM ACTIVE PRICE LIST'!$A$2:$F$1022,5,FALSE),"") | AC16: =+IF($C16>0,VLOOKUP($B16,'CSM ACTIVE PRICE LIST'!$A$2:$F$1022,6,FALSE),"") | AE16: =+H16&J16 -> 0 | AG16: =IF($C16>0,+VLOOKUP(E16,'MASTER CODE DATA'!A$1:B$99,2,FALSE),"") | AH16: =IF(C16>0,+VLOOKUP(F16,'MASTER CODE DATA'!C$1:D$99,2,FALSE),"") | AI16: =IF(C16>0,+VLOOKUP(G16,'MASTER CODE DATA'!E$1:F$99,2,FALSE),"") | AJ16: =IF(C16>0,+VLOOKUP(H16,'MASTER CODE DATA'!G$1:H$99,2,FALSE),"") | AK16: =IF(C16>0,+VLOOKUP(I16,'MASTER CODE DATA'!I$1:J$99,2,FALSE),"")
A17: 5-COMPETITION NAMES | B17: ANGOLA | D17: =IF(C17>0,+AG17&"."&AI17&AJ17&"_"&AK17,"") | J17: 0 | K17: =IF(C17>0,C17,"") | AA17: =+IF($C17>0,VLOOKUP($B17,'CSM ACTIVE PRICE LIST'!$A$2:$F$1022,4,FALSE),"") | AB17: =+IF($C17>0,VLOOKUP($B17,'CSM ACTIVE PRICE LIST'!$A$2:$F$1022,5,FALSE),"") | AC17: =+IF($C17>0,VLOOKUP($B17,'CSM ACTIVE PRICE LIST'!$A$2:$F$1022,6,FALSE),"") | AE17: =+H17&J17 -> 0 | AG17: =IF($C17>0,+VLOOKUP(E17,'MASTER CODE DATA'!A$1:B$99,2,FALSE),"") | AH17: =IF(C17>0,+VLOOKUP(F17,'MASTER CODE DATA'!C$1:D$99,2,FALSE),"") | AI17: =IF(C17>0,+VLOOKUP(G17,'MASTER CODE DATA'!E$1:F$99,2,FALSE),"") | AJ17: =IF(C17>0,+VLOOKUP(H17,'MASTER CODE DATA'!G$1:H$99,2,FALSE),"") | AK17: =IF(C17>0,+VLOOKUP(I17,'MASTER CODE DATA'!I$1:J$99,2,FALSE),"")
A18: 5-COMPETITION NAMES | B18: AREZZO | C18: MEN'S PRO COMPETITION JACKET | D18: =IF(C18>0,+AG18&"."&AI18&AJ18&"_"&AK18,"") -> R.J&TMN_CJK | E18: RIDER | F18: MEN | G18: JACKETS & TAILCOATS | H18: MEN | I18: COMPETITION JACKETS | J18: COMPETITION JACKETS | K18: =IF(C18>0,C18,"") -> MEN'S PRO COMPETITION JACKET | L18: MADE IN ITALY WITH PREMIUM ITALIAN FABRICS Professional Series Competition jacket with soft-shell microfibre that is waterproof, highly elastic and breathable technical jersey fabric. Machine washable | M18: *Italian Premium fabric *Extra-soft and comfortable technical jersey * 4-way stretch fabric * Breathable and Quick Dry * Wrinkle-free and Easy Care Composition: 74% Micro PA / 26% Elasthane | N18: Machine Wash at 30°C Mild process Iron at low temperature Iron from REVERSE Do NOT iron on logos or prints Do not bleach Do NOT Tumble Dry | O18: ERKEK PRO YARIŞMA CEKETİ | P18: EN İYİ KALİTE İTALYAN KUMAŞLAR İLE İTALYA'DA ÜRETİLMİŞTİR Dört yöne esneyen mikrofiberden üretilmiş Profesyonel Seri Yarış Ceketi; su geçirmez, yüksek elastikiyetli ve nefes alabilir teknik örme kumaştan oluşur. Makinede yıkanabilir. | Q18: *İtalyan Premium kumaş *Ekstra yumuşak ve konforlu teknik jarse *4 yönlü esneme özelliği *Nefes alabilir ve hızlı kurur *Kırışmaz ve kolay bakım Bileşimi: %72 Mikro PA / %28 Elastan | R18: Makinede 30°C' de Yıkayın Hassas Yıkama Ilık ütü yapın Tersten ütüleyin Logo ve baskıları ÜTÜLEMEYİN Çamaşır suyu kullanmayın Kurutma Makinesinde Kurutmayın | S18: GIACCHE PRO DA GARA DA UOMO | T18: PRODOTTO IN ITALIA CON TESSUTI ITALIANI DI ALTA QUALITÀ Giacca in microfibra Sensitive ad elevate prestazioni, estremamente elastica e traspirante. Lavabile in lavatrice. Grazie allo studio e alla particolare costruzione delle cuciture di spalle e dorso garantisce una perfetta vestibilità. | U18: *Tessuto premium italiano *Jersey tecnico extra morbido e confortevole *Tessuto elasticizzato in 4 direzioni *Traspirante e ad asciugatura rapida *Antipiega e facile da curare Composizione: 74% Micro PA / 26% Elastan | V18: Lavare in lavatrice a 30°C Ciclo delicato Stirare a bassa temperatura Stirare al rovescio Non stirare su loghi o stampe Non candeggiare Non asciugare in asciugatrice | AA18: =+IF($C18>0,VLOOKUP($B18,'CSM ACTIVE PRICE LIST'!$A$2:$F$1022,4,FALSE),"") -> 449.9 | AB18: =+IF($C18>0,VLOOKUP($B18,'CSM ACTIVE PRICE LIST'!$A$2:$F$1022,5,FALSE),"") -> 24740 | AC18: =+IF($C18>0,VLOOKUP($B18,'CSM ACTIVE PRICE LIST'!$A$2:$F$1022,6,FALSE),"") -> 517.385 | AD18: =+VLOOKUP(B18,'SKU LIST - LINKED'!C:W,21,FALSE) -> XS / 42;S / 44;M / 46;L / 48;XL / 50;XXL / 52 | AE18: =+H18&"-"&J18 -> MEN-COMPETITION JACKETS | AF18: =+VLOOKUP(B18,'[1]STYLES & SIZE CHARTS'!$A:$H,8,FALSE) -> MJT-CJ1 | AG18: =IF($C18>0,+VLOOKUP(E18,'MASTER CODE DATA'!A$1:B$99,2,FALSE),"") -> R | AH18: =IF(C18>0,+VLOOKUP(F18,'MASTER CODE DATA'!C$1:D$99,2,FALSE),"") -> MEN | AI18: =IF(C18>0,+VLOOKUP(G18,'MASTER CODE DATA'!E$1:F$99,2,FALSE),"") -> J&T | AJ18: =IF(C18>0,+VLOOKUP(H18,'MASTER CODE DATA'!G$1:H$99,2,FALSE),"") -> MN | AK18: =IF(C18>0,+VLOOKUP(I18,'MASTER CODE DATA'!I$1:J$99,2,FALSE),"") -> CJK
A19: 5-COMPETITION NAMES | B19: AREZZO-TBF | C19: MEN'S PRO COMPETITION JACKET X TEAM TÜRKİYE | D19: =IF(C19>0,+AG19&"."&AI19&AJ19&"_"&AK19,"") -> R.J&TMN_CJK | E19: RIDER | F19: MEN | G19: JACKETS & TAILCOATS | H19: MEN | I19: COMPETITION JACKETS | J19: COMPETITION JACKETS | K19: =IF(C19>0,C19,"") -> MEN'S PRO COMPETITION JACKET X TEAM TÜRKİYE | L19: MADE IN ITALY WITH PREMIUM ITALIAN FABRICS Professional Series Competition jacket with soft-shell microfibre that is waterproof, highly elastic and breathable technical jersey fabric. Machine washable | M19: *Italian Premium fabric *Extra-soft and comfortable technical jersey * 4-way stretch fabric * Breathable and Quick Dry * Wrinkle-free and Easy Care Composition: 74% Micro PA / 26% Elasthane | N19: Machine Wash at 30°C Mild process Iron at low temperature Iron from REVERSE Do NOT iron on logos or prints Do not bleach Do NOT Tumble Dry | O19: ERKEK PRO YARIŞMA CEKETİ X TEAM TÜRKİYE | P19: EN İYİ KALİTE İTALYAN KUMAŞLAR İLE İTALYA'DA ÜRETİLMİŞTİR Dört yöne esneyen mikrofiberden üretilmiş Profesyonel Seri Yarış Ceketi; su geçirmez, yüksek elastikiyetli ve nefes alabilir teknik örme kumaştan oluşur. Makinede yıkanabilir. | Q19: *İtalyan Premium kumaş *Ekstra yumuşak ve konforlu teknik jarse *4 yönlü esneme özelliği *Nefes alabilir ve hızlı kurur *Kırışmaz ve kolay bakım Bileşimi: %72 Mikro PA / %28 Elastan | R19: Makinede 30°C' de Yıkayın Hassas Yıkama Ilık ütü yapın Tersten ütüleyin Logo ve baskıları ÜTÜLEMEYİN Çamaşır suyu kullanmayın Kurutma Makinesinde Kurutmayın | S19: GIACCHE PRO DA GARA DA UOMO X TEAM TÜRKİYE | T19: PRODOTTO IN ITALIA CON TESSUTI ITALIANI DI ALTA QUALITÀ Giacca in microfibra Sensitive ad elevate prestazioni, estremamente elastica e traspirante. Lavabile in lavatrice. Grazie allo studio e alla particolare costruzione delle cuciture di spalle e dorso garantisce una perfetta vestibilità. | U19: *Tessuto premium italiano *Jersey tecnico extra morbido e confortevole *Tessuto elasticizzato in 4 direzioni *Traspirante e ad asciugatura rapida *Antipiega e facile da curare Composizione: 74% Micro PA / 26% Elastan | V19: Lavare in lavatrice a 30°C Ciclo delicato Stirare a bassa temperatura Stirare al rovescio Non stirare su loghi o stampe Non candeggiare Non asciugare in asciugatrice | AA19: =+IF($C19>0,VLOOKUP($B19,'CSM ACTIVE PRICE LIST'!$A$2:$F$1022,4,FALSE),"") -> 499.9 | AB19: =+IF($C19>0,VLOOKUP($B19,'CSM ACTIVE PRICE LIST'!$A$2:$F$1022,5,FALSE),"") -> 27490 | AC19: =+IF($C19>0,VLOOKUP($B19,'CSM ACTIVE PRICE LIST'!$A$2:$F$1022,6,FALSE),"") -> 574.885 | AD19: =+VLOOKUP(B19,'SKU LIST - LINKED'!C:W,21,FALSE) -> XS / 42;S / 44;M / 46;L / 48;XL / 50;XXL / 52 | AE19: =+H19&"-"&J19 -> MEN-COMPETITION JACKETS | AF19: =+VLOOKUP(B19,'[1]STYLES & SIZE CHARTS'!$A:$H,8,FALSE) -> MJT-CJ1 | AG19: =IF($C19>0,+VLOOKUP(E19,'MASTER CODE DATA'!A$1:B$99,2,FALSE),"") -> R | AH19: =IF(C19>0,+VLOOKUP(F19,'MASTER CODE DATA'!C$1:D$99,2,FALSE),"") -> MEN | AI19: =IF(C19>0,+VLOOKUP(G19,'MASTER CODE DATA'!E$1:F$99,2,FALSE),"") -> J&T | AJ19: =IF(C19>0,+VLOOKUP(H19,'MASTER CODE DATA'!G$1:H$99,2,FALSE),"") -> MN | AK19: =IF(C19>0,+VLOOKUP(I19,'MASTER CODE DATA'!I$1:J$99,2,FALSE),"") -> CJK
A20: 4-GENERAL USE NAMES | B20: ARGENTINA | D20: =IF(C20>0,+AG20&"."&AI20&AJ20&"_"&AK20,"") | J20: 0 | K20: =IF(C20>0,C20,"") | AA20: =+IF($C20>0,VLOOKUP($B20,'CSM ACTIVE PRICE LIST'!$A$2:$F$1022,4,FALSE),"") | AB20: =+IF($C20>0,VLOOKUP($B20,'CSM ACTIVE PRICE LIST'!$A$2:$F$1022,5,FALSE),"") | AC20: =+IF($C20>0,VLOOKUP($B20,'CSM ACTIVE PRICE LIST'!$A$2:$F$1022,6,FALSE),"") | AE20: =+H20&J20 -> 0 | AG20: =IF($C20>0,+VLOOKUP(E20,'MASTER CODE DATA'!A$1:B$99,2,FALSE),"") | AH20: =IF(C20>0,+VLOOKUP(F20,'MASTER CODE DATA'!C$1:D$99,2,FALSE),"") | AI20: =IF(C20>0,+VLOOKUP(G20,'MASTER CODE DATA'!E$1:F$99,2,FALSE),"") | AJ20: =IF(C20>0,+VLOOKUP(H20,'MASTER CODE DATA'!G$1:H$99,2,FALSE),"") | AK20: =IF(C20>0,+VLOOKUP(I20,'MASTER CODE DATA'!I$1:J$99,2,FALSE),"")
A21: 7-KADIN İÇİN UYGUN İSİMLER | B21: ARIZONA | D21: =IF(C21>0,+AG21&"."&AI21&AJ21&"_"&AK21,"") | J21: 0 | K21: =IF(C21>0,C21,"") | AA21: =+IF($C21>0,VLOOKUP($B21,'CSM ACTIVE PRICE LIST'!$A$2:$F$1022,4,FALSE),"") | AB21: =+IF($C21>0,VLOOKUP($B21,'CSM ACTIVE PRICE LIST'!$A$2:$F$1022,5,FALSE),"") | AC21: =+IF($C21>0,VLOOKUP($B21,'CSM ACTIVE PRICE LIST'!$A$2:$F$1022,6,FALSE),"") | AE21: =+H21&J21 -> 0 | AG21: =IF($C21>0,+VLOOKUP(E21,'MASTER CODE DATA'!A$1:B$99,2,FALSE),"") | AH21: =IF(C21>0,+VLOOKUP(F21,'MASTER CODE DATA'!C$1:D$99,2,FALSE),"") | AI21: =IF(C21>0,+VLOOKUP(G21,'MASTER CODE DATA'!E$1:F$99,2,FALSE),"") | AJ21: =IF(C21>0,+VLOOKUP(H21,'MASTER CODE DATA'!G$1:H$99,2,FALSE),"") | AK21: =IF(C21>0,+VLOOKUP(I21,'MASTER CODE DATA'!I$1:J$99,2,FALSE),"")
A22: 4-GENERAL USE NAMES | B22: ARKANSAS | D22: =IF(C22>0,+AG22&"."&AI22&AJ22&"_"&AK22,"") | J22: 0 | K22: =IF(C22>0,C22,"") | AA22: =+IF($C22>0,VLOOKUP($B22,'CSM ACTIVE PRICE LIST'!$A$2:$F$1022,4,FALSE),"") | AB22: =+IF($C22>0,VLOOKUP($B22,'CSM ACTIVE PRICE LIST'!$A$2:$F$1022,5,FALSE),"") | AC22: =+IF($C22>0,VLOOKUP($B22,'CSM ACTIVE PRICE LIST'!$A$2:$F$1022,6,FALSE),"") | AE22: =+H22&J22 -> 0 | AG22: =IF($C22>0,+VLOOKUP(E22,'MASTER CODE DATA'!A$1:B$99,2,FALSE),"") | AH22: =IF(C22>0,+VLOOKUP(F22,'MASTER CODE DATA'!C$1:D$99,2,FALSE),"") | AI22: =IF(C22>0,+VLOOKUP(G22,'MASTER CODE DATA'!E$1:F$99,2,FALSE),"") | AJ22: =IF(C22>0,+VLOOKUP(H22,'MASTER CODE DATA'!G$1:H$99,2,FALSE),"") | AK22: =IF(C22>0,+VLOOKUP(I22,'MASTER CODE DATA'!I$1:J$99,2,FALSE),"")
A23: 4-GENERAL USE NAMES | B23: ASINARA | D23: =IF(C23>0,+AG23&"."&AI23&AJ23&"_"&AK23,"") | J23: 0 | K23: =IF(C23>0,C23,"") | AA23: =+IF($C23>0,VLOOKUP($B23,'CSM ACTIVE PRICE LIST'!$A$2:$F$1022,4,FALSE),"") | AB23: =+IF($C23>0,VLOOKUP($B23,'CSM ACTIVE PRICE LIST'!$A$2:$F$1022,5,FALSE),"") | AC23: =+IF($C23>0,VLOOKUP($B23,'CSM ACTIVE PRICE LIST'!$A$2:$F$1022,6,FALSE),"") | AE23: =+H23&J23 -> 0 | AG23: =IF($C23>0,+VLOOKUP(E23,'MASTER CODE DATA'!A$1:B$99,2,FALSE),"") | AH23: =IF(C23>0,+VLOOKUP(F23,'MASTER CODE DATA'!C$1:D$99,2,FALSE),"") | AI23: =IF(C23>0,+VLOOKUP(G23,'MASTER CODE DATA'!E$1:F$99,2,FALSE),"") | AJ23: =IF(C23>0,+VLOOKUP(H23,'MASTER CODE DATA'!G$1:H$99,2,FALSE),"") | AK23: =IF(C23>0,+VLOOKUP(I23,'MASTER CODE DATA'!I$1:J$99,2,FALSE),"")
A24: 2-WINTER NAMES | B24: ASPEN | C24: WOMEN'S LONG SLEEVE BASE LAYER QUARTER ZIP | D24: =IF(C24>0,+AG24&"."&AI24&AJ24&"_"&AK24,"") -> R.TOPWN_BLY | E24: RIDER | F24: WOMEN | G24: TOPS | H24: WOMEN | I24: BASE LAYERS | J24: BASE LAYERS | K24: =IF(C24>0,C24,"") -> WOMEN'S LONG SLEEVE BASE LAYER QUARTER ZIP | L24: ASPEN Quarter Zip Base Layer / Second Skin Chic, comfortable and technical These elegant base layers are designed to ride and train in style. Available in many colors to match your horse's gear. | M24: *Extra-soft and comfortable technical jersey * 4-way stretch fabric * Breathable and Quick Dry * Wrinkle-free and Easy Care Composition: 90% Polyamide 10% Elasthane | N24: Machine Wash at 30°C Mild process Iron at low temperature Iron from REVERSE Do NOT iron on logos or prints Do not bleach Do NOT Tumble Dry | O24: KADIN UZUN KOL FERMUARLI T-SHIRT | P24: ASPEN Fermuarlı Uzun Kol Antrenman T-shirt / Second Skin Şık, konforlu ve teknik Bu zarif t-shirtler, şık bir şekilde ata binmeniz ve antrenman yapmanız için tasarlanmıştır. Atınızda kullandığınız malzemelerle uyumlu olması için birçok renk seçeneği mevcuttur. | Q24: *Ekstra yumuşak ve rahat teknik örme kumaş * 4 yöne esneyen kumaş * Nefes Alabilir ve Hızlı Kuruma * Kırışmaz ve Bakımı Kolay Kompozisyon: %90 Polyamid %10 Elastan | R24: Makinede 30°C' de Yıkayın Hassas Yıkama Ilık ütü yapın Tersten ütüleyin Logo ve baskıları ÜTÜLEMEYİN Çamaşır suyu kullanmayın Kurutma Makinesinde Kurutmayın | S24: MAGILETTA DONNA MANICA LUNGA QUARTER ZIP | T24: ASPEN Maglietta tecnica a mezza zip / Second Skin Chic, confortevole e tecnica Queste magliette elegante sono progettati per cavalcare e allenarsi con stile Disponibile in molti colori per abbinarsi all'attrezzatura del tuo cavallo | U24: Jersey tecnico extra-morbido e confortevole Tessuto elasticizzato 4-way stretch Traspirante e ad asciugatura rapida No stiro e di facile manutenzione Composizione: 90% Poliammide, 10% Elastan | V24: Lavare in lavatrice a 30°C Ciclo delicato Stirare a bassa temperatura Stirare al rovescio Non stirare su loghi o stampe Non candeggiare Non asciugare in asciugatrice | AA24: =+IF($C24>0,VLOOKUP($B24,'CSM ACTIVE PRICE LIST'!$A$2:$F$1022,4,FALSE),"") -> 99.9 | AB24: =+IF($C24>0,VLOOKUP($B24,'CSM ACTIVE PRICE LIST'!$A$2:$F$1022,5,FALSE),"") -> 5490 | AC24: =+IF($C24>0,VLOOKUP($B24,'CSM ACTIVE PRICE LIST'!$A$2:$F$1022,6,FALSE),"") -> 114.885 | AD24: =+VLOOKUP(B24,'SKU LIST - LINKED'!C:W,21,FALSE) -> XS;S;M;L;XL | AE24: =+H24&"-"&J24 -> WOMEN-BASE LAYERS | AF24: =+VLOOKUP(B24,'[1]STYLES & SIZE CHARTS'!$A:$H,8,FALSE) -> WT-LSBL1 | AG24: =IF($C24>0,+VLOOKUP(E24,'MASTER CODE DATA'!A$1:B$99,2,FALSE),"") -> R | AH24: =IF(C24>0,+VLOOKUP(F24,'MASTER CODE DATA'!C$1:D$99,2,FALSE),"") -> WMN | AI24: =IF(C24>0,+VLOOKUP(G24,'MASTER CODE DATA'!E$1:F$99,2,FALSE),"") -> TOP | AJ24: =IF(C24>0,+VLOOKUP(H24,'MASTER CODE DATA'!G$1:H$99,2,FALSE),"") -> WN | AK24: =IF(C24>0,+VLOOKUP(I24,'MASTER CODE DATA'!I$1:J$99,2,FALSE),"") -> BLY
B25: ASPEN-STRASS | C25: WOMEN'S LONG SLEEVE BASE LAYER QUARTER ZIP WITH STRASS | D25: =IF(C25>0,+AG25&"."&AI25&AJ25&"_"&AK25,"") -> R.TOPWN_BLY | E25: RIDER | F25: WOMEN | G25: TOPS | H25: WOMEN | I25: BASE LAYERS | J25: BASE LAYERS | K25: =IF(C25>0,C25,"") -> WOMEN'S LONG SLEEVE BASE LAYER QUARTER ZIP WITH STRASS | L25: ASPEN Quarter Zip Base Layer / Second Skin Your favorite base layers now come with a touch of Strass to elavate your elegance and shine. Chic, comfortable and technical These elegant base layers are designed to ride and train in style. Available in many colors to match your horse's gear. | M25: *Extra-soft and comfortable technical jersey * 4-way stretch fabric * Breathable and Quick Dry * Wrinkle-free and Easy Care Composition: 90% Polyamide 10% Elasthane | N25: Machine Wash at 30°C Mild process Iron at low temperature Iron from REVERSE Do NOT iron on logos or prints Do not bleach Do NOT Tumble Dry | O25: STRASS TAŞ DETAYLI KADIN UZUN KOL FERMUARLI T-SHIRT | P25: ASPEN Fermuarlı Uzun Kol Antrenman T-shirt / Second Skin En sevdiğiniz base layerlar, zarafetinizi ve ışıltınızı artırmak için artık Strass taş detayına sahip. Şık, konforlu ve teknik Bu zarif t-shirtler, şık bir şekilde ata binmeniz ve antrenman yapmanız için tasarlanmıştır. Atınızda kullandığınız malzemelerle uyumlu olması için birçok renk seçeneği mevcuttur. | Q25: *Ekstra yumuşak ve rahat teknik örme kumaş * 4 yöne esneyen kumaş * Nefes Alabilir ve Hızlı Kuruma * Kırışmaz ve Bakımı Kolay Kompozisyon: %90 Polyamid %10 Elastan | R25: Makinede 30°C' de Yıkayın Hassas Yıkama Ilık ütü yapın Tersten ütüleyin Logo ve baskıları ÜTÜLEMEYİN Çamaşır suyu kullanmayın Kurutma Makinesinde Kurutmayın | S25: MAGILETTA DONNA MANICA LUNGA QUARTER ZIP CON STRASS | T25: ASPEN Maglietta tecnica a mezza zip / Second Skin I tuoi base layer preferiti ora arrivano con un tocco di strass per elevare la tua eleganza e brillantezza. Chic, confortevole e tecnica Queste magliette elegante sono progettati per cavalcare e allenarsi con stile Disponibile in molti colori per abbinarsi all'attrezzatura del tuo cavallo | U25: Jersey tecnico extra-morbido e confortevole Tessuto elasticizzato 4-way stretch Traspirante e ad asciugatura rapida No stiro e di facile manutenzione Composizione: 90% Poliammide, 10% Elastan | V25: Lavare in lavatrice a 30°C Ciclo delicato Stirare a bassa temperatura Stirare al rovescio Non stirare su loghi o stampe Non candeggiare Non asciugare in asciugatrice | AA25: =+IF($C25>0,VLOOKUP($B25,'CSM ACTIVE PRICE LIST'!$A$2:$F$1022,4,FALSE),"") -> 119.9 | AB25: =+IF($C25>0,VLOOKUP($B25,'CSM ACTIVE PRICE LIST'!$A$2:$F$1022,5,FALSE),"") -> 6590 | AC25: =+IF($C25>0,VLOOKUP($B25,'CSM ACTIVE PRICE LIST'!$A$2:$F$1022,6,FALSE),"") -> 137.885 | AD25: =+VLOOKUP(B25,'SKU LIST - LINKED'!C:W,21,FALSE) -> XS;S;M;L;XL;XXL | AE25: =+H25&"-"&J25 -> WOMEN-BASE LAYERS | AF25: =+VLOOKUP(B25,'[1]STYLES & SIZE CHARTS'!$A:$H,8,FALSE) -> WT-LSBL1 | AG25: =IF($C25>0,+VLOOKUP(E25,'MASTER CODE DATA'!A$1:B$99,2,FALSE),"") -> R | AH25: =IF(C25>0,+VLOOKUP(F25,'MASTER CODE DATA'!C$1:D$99,2,FALSE),"") -> WMN | AI25: =IF(C25>0,+VLOOKUP(G25,'MASTER CODE DATA'!E$1:F$99,2,FALSE),"") -> TOP | AJ25: =IF(C25>0,+VLOOKUP(H25,'MASTER CODE DATA'!G$1:H$99,2,FALSE),"") -> WN | AK25: =IF(C25>0,+VLOOKUP(I25,'MASTER CODE DATA'!I$1:J$99,2,FALSE),"") -> BLY
A26: 2-WINTER NAMES | B26: ASPEN-JR | C26: GIRL'S LONG SLEEVE BASE LAYER QUARTER ZIP | D26: =IF(C26>0,+AG26&"."&AI26&AJ26&"_"&AK26,"") -> R.TOPKG_BLY | E26: RIDER | F26: JUNIOR | G26: TOPS | H26: KIDS GIRL | I26: BASE LAYERS | J26: BASE LAYERS | K26: =IF(C26>0,C26,"") -> GIRL'S LONG SLEEVE BASE LAYER QUARTER ZIP | L26: ASPEN-JR Quarter Zip Base Layer / Second Skin Chic, comfortable and technical These elegant base layers are designed to ride and train in style. Available in many colors to match your horse's gear. | M26: *Extra-soft and comfortable technical jersey * 4-way stretch fabric * Breathable and Quick Dry * Wrinkle-free and Easy Care Composition: 90% Polyamide 10% Elasthane | N26: Machine Wash at 30°C Mild process Iron at low temperature Iron from REVERSE Do NOT iron on logos or prints Do not bleach Do NOT Tumble Dry | O26: KIZ ÇOCUK UZUN KOL FERMUARLI T-SHIRT | P26: ASPEN-JR Genç Biniciler için Fermuarlı Uzun Kol Antrenman T-shirt / Second Skin Şık, konforlu ve teknik Bu zarif t-shirtler, şık bir şekilde ata binmeniz ve antrenman yapmanız için tasarlanmıştır. Atınızda kullandığınız malzemelerle uyumlu olması için birçok renk seçeneği mevcuttur. | Q26: *Ekstra yumuşak ve rahat teknik örme kumaş * 4 yöne esneyen kumaş * Nefes Alabilir ve Hızlı Kuruma * Kırışmaz ve Bakımı Kolay Kompozisyon: %90 Polyamid %10 Elastan | R26: Makinede 30°C' de Yıkayın Hassas Yıkama Ilık ütü yapın Tersten ütüleyin Logo ve baskıları ÜTÜLEMEYİN Çamaşır suyu kullanmayın Kurutma Makinesinde Kurutmayın | S26: MAGLIETTA RAGAZZA MANICA LUNGA QUARTER ZIP | T26: ASPEN-JR Maglietta tecnica a mezza zip / Second Skin Chic, confortevole e tecnica Queste magliette elegante sono progettati per cavalcare e allenarsi con stile Disponibile in molti colori per abbinarsi all'attrezzatura del tuo cavallo | U26: Jersey tecnico extra-morbido e confortevole Tessuto elasticizzato 4-way stretch Traspirante e ad asciugatura rapida No stiro e di facile manutenzione Composizione: 90% Poliammide, 10% Elastan | V26: Lavare in lavatrice a 30°C Ciclo delicato Stirare a bassa temperatura Stirare al rovescio Non stirare su loghi o stampe Non candeggiare Non asciugare in asciugatrice | AA26: =+IF($C26>0,VLOOKUP($B26,'CSM ACTIVE PRICE LIST'!$A$2:$F$1022,4,FALSE),"") -> 69.9 | AB26: =+IF($C26>0,VLOOKUP($B26,'CSM ACTIVE PRICE LIST'!$A$2:$F$1022,5,FALSE),"") -> 3840 | AC26: =+IF($C26>0,VLOOKUP($B26,'CSM ACTIVE PRICE LIST'!$A$2:$F$1022,6,FALSE),"") -> 80.385 | AD26: =+VLOOKUP(B26,'SKU LIST - LINKED'!C:W,21,FALSE) -> 6-7 Y;8-9 Y;10-11 Y;12-13 Y;14-15 Y | AE26: =+H26&"-"&J26 -> KIDS GIRL-BASE LAYERS | AF26: =+VLOOKUP(B26,'[1]STYLES & SIZE CHARTS'!$A:$H,8,FALSE) -> JT-GLSP1 | AG26: =IF($C26>0,+VLOOKUP(E26,'MASTER CODE DATA'!A$1:B$99,2,FALSE),"") -> R | AH26: =IF(C26>0,+VLOOKUP(F26,'MASTER CODE DATA'!C$1:D$99,2,FALSE),"") -> JNR | AI26: =IF(C26>0,+VLOOKUP(G26,'MASTER CODE DATA'!E$1:F$99,2,FALSE),"") -> TOP | AJ26: =IF(C26>0,+VLOOKUP(H26,'MASTER CODE DATA'!G$1:H$99,2,FALSE),"") -> KG | AK26: =IF(C26>0,+VLOOKUP(I26,'MASTER CODE DATA'!I$1:J$99,2,FALSE),"") -> BLY
A27: 2-WINTER NAMES | B27: ATLANTA | C27: MEN'S PUFFER VEST | D27: =IF(C27>0,+AG27&"."&AI27&AJ27&"_"&AK27,"") -> R.OTWMN_PUV | E27: RIDER | F27: MEN | G27: OUTERWEAR | H27: MEN | I27: PUFFER VESTS | J27: PUFFER VESTS | K27: =IF(C27>0,C27,"") -> MEN'S PUFFER VEST | L27: ATLANTA Riding Vest Every rider's must have product in the wardrobe Ideal for transition seasons | M27: *Super-light weight Composition: Shell fabric: 100% Nylon Lining: 100% Nylon Filling: 100% Polyester Non-woven | N27: Machine Wash gently at 30 C Do not dry clean Do not bleach Do not iron Hang dry | O27: ERKEK ŞİŞME YELEK | P27: ATLANTA Binici Yeleği Her binicinin gardrobunda bulunması gereken bir ürün Geçiş mevsimleri için ideal | Q27: *Ultra hafif Kompozisyon: Dış Kumaş: 100% Nylon Astar: 100% Nylon Dolgu: 100% Polyester Elyaf | R27: 30 C derecede hassas Makine yıkama Kuru temizleme yapmayın Çamaşır suyu kullanmayın Ütülemeyin Asarak kurutun | S27: GILET IMBOTTITO DA UOMO | T27: Gilet da equitazione Un prodotto essenziale nel guardaroba di ogni cavaliere Ideale per le mezze stagioni | U27: Super leggero Vestibilita slim per le donne Composizione: Tessuto esterno: 100% Nylon Fodera: 100% Nylon Imbottitura: 100% Poliestere | V27: Lavaggio delicato a 30°C Non lavare a secco Non candeggiare Non stirare Asciugare appeso | AA27: =+IF($C27>0,VLOOKUP($B27,'CSM ACTIVE PRICE LIST'!$A$2:$F$1022,4,FALSE),"") -> 99.9 | AB27: =+IF($C27>0,VLOOKUP($B27,'CSM ACTIVE PRICE LIST'!$A$2:$F$1022,5,FALSE),"") -> 5490 | AC27: =+IF($C27>0,VLOOKUP($B27,'CSM ACTIVE PRICE LIST'!$A$2:$F$1022,6,FALSE),"") -> 114.885 | AD27: =+VLOOKUP(B27,'SKU LIST - LINKED'!C:W,21,FALSE) -> XS;S;M;L;XL;XXL | AE27: =+H27&"-"&J27 -> MEN-PUFFER VESTS | AF27: =+VLOOKUP(B27,'[1]STYLES & SIZE CHARTS'!$A:$H,8,FALSE) -> 0 | AG27: =IF($C27>0,+VLOOKUP(E27,'MASTER CODE DATA'!A$1:B$99,2,FALSE),"") -> R | AH27: =IF(C27>0,+VLOOKUP(F27,'MASTER CODE DATA'!C$1:D$99,2,FALSE),"") -> MEN | AI27: =IF(C27>0,+VLOOKUP(G27,'MASTER CODE DATA'!E$1:F$99,2,FALSE),"") -> OTW | AJ27: =IF(C27>0,+VLOOKUP(H27,'MASTER CODE DATA'!G$1:H$99,2,FALSE),"") -> MN | AK27: =IF(C27>0,+VLOOKUP(I27,'MASTER CODE DATA'!I$1:J$99,2,FALSE),"") -> PUV
B28: ATLANTIS | C28: KID'S UNISEX KNEE GRIP PRO BREECHES | D28: =IF(C28>0,+AG28&"."&AI28&AJ28&"_"&AK28,"") -> R.BOTKU_BRC | E28: RIDER | F28: JUNIOR | G28: BOTTOMS | H28: KIDS UNISEX | I28: BREECHES | J28: BREECHES | K28: =IF(C28>0,C28,"") -> KID'S UNISEX KNEE GRIP PRO BREECHES | L28: MADE IN ITALY WITH PREMIUM ITALIAN FABRICS Professional Series Breeches with Bi-stretch microfibre, antibacterical, waterrepellent and breathable technical jersey fabric. Comfortable side pockets with edge and back pockets with flaps and button. Grip knees applied for the best comfort | M28: *Italian Premium fabric *Extra-soft and comfortable technical jersey *4-way stretch fabric *Breathable and Quick Dry *Wrinkle-free and Easy Care *Knee Grip Composition: 74% Micro PA / 26% Elasthane | N28: Machine Wash at 30°C Mild process Iron at low temperature Iron from REVERSE Do NOT iron on logos or prints Do not bleach Do NOT Tumble Dry | O28: ÇOCUK UNISEX BİNİCİ PANTOLONU | P28: EN İYİ KALİTE İTALYAN KUMAŞLAR İLE İTALYA'DA ÜRETİLMİŞTİR Çift yönlü esneyen mikrofiberden üretilmiş Profesyonel Seri Binici Pantolonu; antibakteriyel, su itici ve nefes alabilir teknik jarse kumaştan yapılmıştır. Dizde grip detayları en iyi rahatlığı sağlar. | Q28: *İtalyan Premium kumaş *Ekstra yumuşak ve konforlu teknik jarse *4 yönlü esneme özelliği *Nefes alabilir ve hızlı kurur *Kırışmaz ve kolay bakım *Diz Grip Bileşimi: %74 Mikro PA / %26 Elastan | R28: Makinede 30°C' de Yıkayın Hassas Yıkama Ilık ütü yapın Tersten ütüleyin Logo ve baskıları ÜTÜLEMEYİN Çamaşır suyu kullanmayın Kurutma Makinesinde Kurutmayın | S28: PANTALONI KNEE GRIP PRO JUNIOR | T28: PRODOTTO IN ITALIA CON TESSUTI ITALIANI DI ALTA QUALITÀ Realizzato in microfibra Sensitive extra comfort idrorepellente e traspirante, accompagna i movimenti senza costrizioni ed è ideale per attività fisiche anche prolungate. Fondo elastico per garantire un’ottima calzata, grip applicato al ginocchio per la massima aderenza e comfort | U28: *Tessuto premium italiano *Jersey tecnico extra morbido e confortevole *Tessuto elasticizzato in 4 direzioni *Traspirante e ad asciugatura rapida *Antipiega e facile da curare *Knee Grip Composizione: 74% Micro PA / 26% Elastan | V28: Lavare in lavatrice a 30°C Ciclo delicato Stirare a bassa temperatura Stirare al rovescio Non stirare su loghi o stampe Non candeggiare Non asciugare in asciugatrice | AA28: =+IF($C28>0,VLOOKUP($B28,'CSM ACTIVE PRICE LIST'!$A$2:$F$1022,4,FALSE),"") -> 159.9 | AB28: =+IF($C28>0,VLOOKUP($B28,'CSM ACTIVE PRICE LIST'!$A$2:$F$1022,5,FALSE),"") -> 8790 | AC28: =+IF($C28>0,VLOOKUP($B28,'CSM ACTIVE PRICE LIST'!$A$2:$F$1022,6,FALSE),"") -> 183.885 | AD28: =+VLOOKUP(B28,'SKU LIST - LINKED'!C:W,21,FALSE) -> 6-7 Y;8-9 Y;10-11 Y;12-13 Y;14-15 Y | AE28: =+H28&"-"&J28 -> KIDS UNISEX-BREECHES | AF28: =+VLOOKUP(B28,'[1]STYLES & SIZE CHARTS'!$A:$H,8,FALSE) -> JB-UB1 | AG28: =IF($C28>0,+VLOOKUP(E28,'MASTER CODE DATA'!A$1:B$99,2,FALSE),"") -> R | AH28: =IF(C28>0,+VLOOKUP(F28,'MASTER CODE DATA'!C$1:D$99,2,FALSE),"") -> JNR | AI28: =IF(C28>0,+VLOOKUP(G28,'MASTER CODE DATA'!E$1:F$99,2,FALSE),"") -> BOT | AJ28: =IF(C28>0,+VLOOKUP(H28,'MASTER CODE DATA'!G$1:H$99,2,FALSE),"") -> KU | AK28: =IF(C28>0,+VLOOKUP(I28,'MASTER CODE DATA'!I$1:J$99,2,FALSE),"") -> BRC
B29: ATLANTIS-W | C29: KID'S UNISEX KNEE GRIP PRO WINTER BREECHES | D29: =IF(C29>0,+AG29&"."&AI29&AJ29&"_"&AK29,"") -> R.BOTKU_BRC | E29: RIDER | F29: JUNIOR | G29: BOTTOMS | H29: KIDS UNISEX | I29: BREECHES | J29: BREECHES | K29: =IF(C29>0,C29,"") -> KID'S UNISEX KNEE GRIP PRO WINTER BREECHES | L29: MADE IN ITALY WITH PREMIUM ITALIAN FABRICS Professional Series Winter Breeches with Bi-stretch microfibre, antibacterical, waterrepellent and breathable technical jersey fabric on the surface and a heat tech polar fabric on the inside to keep you warm during cold weather conditions and provide full movement whatever your discipline . Comfortable side pockets with edge and back pockets with flaps and button. Grip knees applied for the best comfort | M29: *Italian Premium fabric *Extra-soft and comfortable technical jersey with heat tech polar fabric inside *4-way stretch fabric *Breathable and Quick Dry *Wrinkle-free and Easy Care *Knee Grip Composition: 74% Micro PA / 26% Elasthane | N29: Machine Wash at 30°C Mild process Iron at low temperature Iron from REVERSE Do NOT iron on logos or prints Do not bleach Do NOT Tumble Dry | O29: KIŞLIK ÇOCUK UNISEX BİNİCİ PANTOLONU | P29: EN İYİ KALİTE İTALYAN KUMAŞLAR İLE İTALYA'DA ÜRETİLMİŞTİR Çift yönlü esneyen mikrofiberden üretilmiş Profesyonel Seri Binici Pantolonu; dış yüzeyde antibakteriyel, su itici ve nefes alabilir teknik jarse kumaştan ve iç kısmında ısı tutan polar kumaştan yapılmıştır. Soğuk hava şartlarında kullanmak için idealdir. Dizde grip detayları en iyi rahatlığı sağlar. | Q29: *İtalyan Premium kumaş *Dışı ekstra yumuşak ve konforlu teknik jarse, içi ısı tutan polar kumaş *4 yönlü esneme özelliği *Nefes alabilir ve hızlı kurur *Kırışmaz ve kolay bakım *Diz Grip Bileşimi: %74 Mikro PA / %26 Elastan | R29: Makinede 30°C' de Yıkayın Hassas Yıkama Ilık ütü yapın Tersten ütüleyin Logo ve baskıları ÜTÜLEMEYİN Çamaşır suyu kullanmayın Kurutma Makinesinde Kurutmayın | S29: PANTALONI INVERNALI KNEE GRIP PRO JUNIOR | T29: PRODOTTO IN ITALIA CON TESSUTI ITALIANI DI ALTA QUALITÀ Realizzato in faccia con tessuto microfibra Sensitive extra comfort idrorepellente e traspirante, e dentro con felpa heat tech per tenervi caldo nei ambienti molto freddi. Ideale per attività fisiche anche prolungate. Fondo elastico per garantire un’ottima calzata, grip applicato al ginocchio per la massima aderenza e comfort | U29: *Tessuto premium italiano *Jersey tecnico extra morbido e confortevole con felpa heat tech dentro *Tessuto elasticizzato in 4 direzioni *Traspirante e ad asciugatura rapida *Antipiega e facile da curare *Knee Grip Composizione: 74% Micro PA / 26% Elastan | V29: Lavare in lavatrice a 30°C Ciclo delicato Stirare a bassa temperatura Stirare al rovescio Non stirare su loghi o stampe Non candeggiare Non asciugare in asciugatrice | AA29: =+IF($C29>0,VLOOKUP($B29,'CSM ACTIVE PRICE LIST'!$A$2:$F$1022,4,FALSE),"") -> 169.9 | AB29: =+IF($C29>0,VLOOKUP($B29,'CSM ACTIVE PRICE LIST'!$A$2:$F$1022,5,FALSE),"") -> 9340 | AC29: =+IF($C29>0,VLOOKUP($B29,'CSM ACTIVE PRICE LIST'!$A$2:$F$1022,6,FALSE),"") -> 195.385 | AD29: =+VLOOKUP(B29,'SKU LIST - LINKED'!C:W,21,FALSE) -> 6-7 Y;8-9 Y;10-11 Y;12-13 Y;14-15 Y | AE29: =+H29&"-"&J29 -> KIDS UNISEX-BREECHES | AF29: =+VLOOKUP(B29,'[1]STYLES & SIZE CHARTS'!$A:$H,8,FALSE) -> JB-UB1 | AG29: =IF($C29>0,+VLOOKUP(E29,'MASTER CODE DATA'!A$1:B$99,2,FALSE),"") -> R | AH29: =IF(C29>0,+VLOOKUP(F29,'MASTER CODE DATA'!C$1:D$99,2,FALSE),"") -> JNR | AI29: =IF(C29>0,+VLOOKUP(G29,'MASTER CODE DATA'!E$1:F$99,2,FALSE),"") -> BOT | AJ29: =IF(C29>0,+VLOOKUP(H29,'MASTER CODE DATA'!G$1:H$99,2,FALSE),"") -> KU | AK29: =IF(C29>0,+VLOOKUP(I29,'MASTER CODE DATA'!I$1:J$99,2,FALSE),"") -> BRC
A30: 5-COMPETITION NAMES | B30: AUGUSTA | D30: =IF(C30>0,+AG30&"."&AI30&AJ30&"_"&AK30,"") | J30: 0 | K30: =IF(C30>0,C30,"") | AA30: =+IF($C30>0,VLOOKUP($B30,'CSM ACTIVE PRICE LIST'!$A$2:$F$1022,4,FALSE),"") | AB30: =+IF($C30>0,VLOOKUP($B30,'CSM ACTIVE PRICE LIST'!$A$2:$F$1022,5,FALSE),"") | AC30: =+IF($C30>0,VLOOKUP($B30,'CSM ACTIVE PRICE LIST'!$A$2:$F$1022,6,FALSE),"") | AE30: =+H30&J30 -> 0 | AG30: =IF($C30>0,+VLOOKUP(E30,'MASTER CODE DATA'!A$1:B$99,2,FALSE),"") | AH30: =IF(C30>0,+VLOOKUP(F30,'MASTER CODE DATA'!C$1:D$99,2,FALSE),"") | AI30: =IF(C30>0,+VLOOKUP(G30,'MASTER CODE DATA'!E$1:F$99,2,FALSE),"") | AJ30: =IF(C30>0,+VLOOKUP(H30,'MASTER CODE DATA'!G$1:H$99,2,FALSE),"") | AK30: =IF(C30>0,+VLOOKUP(I30,'MASTER CODE DATA'!I$1:J$99,2,FALSE),"")
A31: 5-COMPETITION NAMES | B31: AUSTIN | D31: =IF(C31>0,+AG31&"."&AI31&AJ31&"_"&AK31,"") | J31: 0 | K31: =IF(C31>0,C31,"") | AA31: =+IF($C31>0,VLOOKUP($B31,'CSM ACTIVE PRICE LIST'!$A$2:$F$1022,4,FALSE),"") | AB31: =+IF($C31>0,VLOOKUP($B31,'CSM ACTIVE PRICE LIST'!$A$2:$F$1022,5,FALSE),"") | AC31: =+IF($C31>0,VLOOKUP($B31,'CSM ACTIVE PRICE LIST'!$A$2:$F$1022,6,FALSE),"") | AE31: =+H31&J31 -> 0 | AG31: =IF($C31>0,+VLOOKUP(E31,'MASTER CODE DATA'!A$1:B$99,2,FALSE),"") | AH31: =IF(C31>0,+VLOOKUP(F31,'MASTER CODE DATA'!C$1:D$99,2,FALSE),"") | AI31: =IF(C31>0,+VLOOKUP(G31,'MASTER CODE DATA'!E$1:F$99,2,FALSE),"") | AJ31: =IF(C31>0,+VLOOKUP(H31,'MASTER CODE DATA'!G$1:H$99,2,FALSE),"") | AK31: =IF(C31>0,+VLOOKUP(I31,'MASTER CODE DATA'!I$1:J$99,2,FALSE),"")
